Workbook

Sheet correlaciones
A1: Misma divisa | X1: Matriz estresada correlaciones
A2: Theta | B2: 0.03 | X2: Escenario | Y2: 1
X3: Tiene un cap en el 100% ==> 54a FRTB
B12: Curva | C12: {=+TRANSPOSE(A14:A33)} -> 1M | D12: 1M | E12: 1M | F12: 1M | G12: 1M | H12: 1M | I12: 1M | J12: 1M | K12: 1M | L12: 1M | M12: 3M | N12: 3M | O12: 3M | P12: 3M | Q12: 3M | R12: 3M | S12: 3M | T12: 3M | U12: 3M | V12: 3M | Y12: Curva | Z12: {=+TRANSPOSE(X14:X33)} -> 1M | AA12: 1M | AB12: 1M | AC12: 1M | AD12: 1M | AE12: 1M | AF12: 1M | AG12: 1M | AH12: 1M | AI12: 1M | AJ12: 3M | AK12: 3M | AL12: 3M | AM12: 3M | AN12: 3M | AO12: 3M | AP12: 3M | AQ12: 3M | AR12: 3M | AS12: 3M
A13: Curva | B13: Tenor | C13: {=+TRANSPOSE(B14:B33)} -> 0.25 | D13: 0.5 | E13: 1 | F13: 2 | G13: 3 | H13: 5 | I13: 10 | J13: 15 | K13: 20 | L13: 30 | M13: 0.25 | N13: 0.5 | O13: 1 | P13: 2 | Q13: 3 | R13: 5 | S13: 10 | T13: 15 | U13: 20 | V13: 30 | X13: Curva | Y13: Tenor | Z13: {=+TRANSPOSE(Y14:Y33)} -> 0.25 | AA13: 0.5 | AB13: 1 | AC13: 2 | AD13: 3 | AE13: 5 | AF13: 10 | AG13: 15 | AH13: 20 | AI13: 30 | AJ13: 0.25 | AK13: 0.5 | AL13: 1 | AM13: 2 | AN13: 3 | AO13: 5 | AP13: 10 | AQ13: 15 | AR13: 20 | AS13: 30
A14: 1M | B14: 0.25 | C14: =+IF(C$12<>$A14,99.9%,1)*MAX(EXP(-$B$2*(ABS(C$13-$B14)/MIN(C$13,$B14))),40%) -> 1 | D14: =+IF(D$12<>$A14,99.9%,1)*MAX(EXP(-$B$2*(ABS(D$13-$B14)/MIN(D$13,$B14))),40%) -> 0.97044553 | E14: =+IF(E$12<>$A14,99.9%,1)*MAX(EXP(-$B$2*(ABS(E$13-$B14)/MIN(E$13,$B14))),40%) -> 0.91393119 | F14: =+IF(F$12<>$A14,99.9%,1)*MAX(EXP(-$B$2*(ABS(F$13-$B14)/MIN(F$13,$B14))),40%) -> 0.81058425 | G14: =+IF(G$12<>$A14,99.9%,1)*MAX(EXP(-$B$2*(ABS(G$13-$B14)/MIN(G$13,$B14))),40%) -> 0.71892373 | H14: =+IF(H$12<>$A14,99.9%,1)*MAX(EXP(-$B$2*(ABS(H$13-$B14)/MIN(H$13,$B14))),40%) -> 0.56552544 | I14: =+IF(I$12<>$A14,99.9%,1)*MAX(EXP(-$B$2*(ABS(I$13-$B14)/MIN(I$13,$B14))),40%) -> 0.4 | J14: =+IF(J$12<>$A14,99.9%,1)*MAX(EXP(-$B$2*(ABS(J$13-$B14)/MIN(J$13,$B14))),40%) -> 0.4 | ... V14: =+IF(V$12<>$A14,99.9%,1)*MAX(EXP(-$B$2*(ABS(V$13-$B14)/MIN(V$13,$B14))),40%) -> 0.3996 | X14: 1M | Y14: 0.25 | Z14: 1 | AA14: =+IF(D14*$Y$2>1,1,D14*$Y$2) -> 0.97044553 | AB14: =+IF(E14*$Y$2>1,1,E14*$Y$2) -> 0.91393119 | AC14: =+IF(F14*$Y$2>1,1,F14*$Y$2) -> 0.81058425 | AD14: =+IF(G14*$Y$2>1,1,G14*$Y$2) -> 0.71892373 | AE14: =+IF(H14*$Y$2>1,1,H14*$Y$2) -> 0.56552544 | AF14: =+IF(I14*$Y$2>1,1,I14*$Y$2) -> 0.4 | AG14: =+IF(J14*$Y$2>1,1,J14*$Y$2) -> 0.4 | AH14: =+IF(K14*$Y$2>1,1,K14*$Y$2) -> 0.4 | ... AS14: =+IF(V14*$Y$2>1,1,V14*$Y$2) -> 0.3996
A15: 1M | B15: 0.5 | C15: =+IF(C$12<>$A15,99.9%,1)*MAX(EXP(-$B$2*(ABS(C$13-$B15)/MIN(C$13,$B15))),40%) -> 0.97044553 | D15: =+IF(D$12<>$A15,99.9%,1)*MAX(EXP(-$B$2*(ABS(D$13-$B15)/MIN(D$13,$B15))),40%) -> 1 | E15: =+IF(E$12<>$A15,99.9%,1)*MAX(EXP(-$B$2*(ABS(E$13-$B15)/MIN(E$13,$B15))),40%) -> 0.97044553 | F15: =+IF(F$12<>$A15,99.9%,1)*MAX(EXP(-$B$2*(ABS(F$13-$B15)/MIN(F$13,$B15))),40%) -> 0.91393119 | G15: =+IF(G$12<>$A15,99.9%,1)*MAX(EXP(-$B$2*(ABS(G$13-$B15)/MIN(G$13,$B15))),40%) -> 0.86070798 | H15: =+IF(H$12<>$A15,99.9%,1)*MAX(EXP(-$B$2*(ABS(H$13-$B15)/MIN(H$13,$B15))),40%) -> 0.76337949 | I15: =+IF(I$12<>$A15,99.9%,1)*MAX(EXP(-$B$2*(ABS(I$13-$B15)/MIN(I$13,$B15))),40%) -> 0.56552544 | J15: =+IF(J$12<>$A15,99.9%,1)*MAX(EXP(-$B$2*(ABS(J$13-$B15)/MIN(J$13,$B15))),40%) -> 0.41895155 | ... V15: =+IF(V$12<>$A15,99.9%,1)*MAX(EXP(-$B$2*(ABS(V$13-$B15)/MIN(V$13,$B15))),40%) -> 0.3996 | X15: 1M | Y15: 0.5 | Z15: =+IF(C15*$Y$2>1,1,C15*$Y$2) -> 0.97044553 | AA15: 1 | AB15: =+IF(E15*$Y$2>1,1,E15*$Y$2) -> 0.97044553 | AC15: =+IF(F15*$Y$2>1,1,F15*$Y$2) -> 0.91393119 | AD15: =+IF(G15*$Y$2>1,1,G15*$Y$2) -> 0.86070798 | AE15: =+IF(H15*$Y$2>1,1,H15*$Y$2) -> 0.76337949 | AF15: =+IF(I15*$Y$2>1,1,I15*$Y$2) -> 0.56552544 | AG15: =+IF(J15*$Y$2>1,1,J15*$Y$2) -> 0.41895155 | AH15: =+IF(K15*$Y$2>1,1,K15*$Y$2) -> 0.4 | AI15: =+IF(L15*$Y$2>1,1,L15*$Y$2) -> 0.4 | ... AS15: =+IF(V15*$Y$2>1,1,V15*$Y$2) -> 0.3996
A16: 1M | B16: 1 | C16: =+IF(C$12<>$A16,99.9%,1)*MAX(EXP(-$B$2*(ABS(C$13-$B16)/MIN(C$13,$B16))),40%) -> 0.91393119 | D16: =+IF(D$12<>$A16,99.9%,1)*MAX(EXP(-$B$2*(ABS(D$13-$B16)/MIN(D$13,$B16))),40%) -> 0.97044553 | E16: =+IF(E$12<>$A16,99.9%,1)*MAX(EXP(-$B$2*(ABS(E$13-$B16)/MIN(E$13,$B16))),40%) -> 1 | F16: =+IF(F$12<>$A16,99.9%,1)*MAX(EXP(-$B$2*(ABS(F$13-$B16)/MIN(F$13,$B16))),40%) -> 0.97044553 | G16: =+IF(G$12<>$A16,99.9%,1)*MAX(EXP(-$B$2*(ABS(G$13-$B16)/MIN(G$13,$B16))),40%) -> 0.94176453 | H16: =+IF(H$12<>$A16,99.9%,1)*MAX(EXP(-$B$2*(ABS(H$13-$B16)/MIN(H$13,$B16))),40%) -> 0.88692044 | I16: =+IF(I$12<>$A16,99.9%,1)*MAX(EXP(-$B$2*(ABS(I$13-$B16)/MIN(I$13,$B16))),40%) -> 0.76337949 | J16: =+IF(J$12<>$A16,99.9%,1)*MAX(EXP(-$B$2*(ABS(J$13-$B16)/MIN(J$13,$B16))),40%) -> 0.65704682 | ... V16: =+IF(V$12<>$A16,99.9%,1)*MAX(EXP(-$B$2*(ABS(V$13-$B16)/MIN(V$13,$B16))),40%) -> 0.4185326 | X16: 1M | Y16: 1 | Z16: =+IF(C16*$Y$2>1,1,C16*$Y$2) -> 0.91393119 | AA16: =+IF(D16*$Y$2>1,1,D16*$Y$2) -> 0.97044553 | AB16: 1 | AC16: =+IF(F16*$Y$2>1,1,F16*$Y$2) -> 0.97044553 | AD16: =+IF(G16*$Y$2>1,1,G16*$Y$2) -> 0.94176453 | AE16: =+IF(H16*$Y$2>1,1,H16*$Y$2) -> 0.88692044 | AF16: =+IF(I16*$Y$2>1,1,I16*$Y$2) -> 0.76337949 | AG16: =+IF(J16*$Y$2>1,1,J16*$Y$2) -> 0.65704682 | AH16: =+IF(K16*$Y$2>1,1,K16*$Y$2) -> 0.56552544 | AI16: =+IF(L16*$Y$2>1,1,L16*$Y$2) -> 0.41895155 | AJ16: =+IF(M16*$Y$2>1,1,M16*$Y$2) -> 0.91301725 | ... AS16: =+IF(V16*$Y$2>1,1,V16*$Y$2) -> 0.4185326
A17: 1M | B17: 2 | C17: =+IF(C$12<>$A17,99.9%,1)*MAX(EXP(-$B$2*(ABS(C$13-$B17)/MIN(C$13,$B17))),40%) -> 0.81058425 | D17: =+IF(D$12<>$A17,99.9%,1)*MAX(EXP(-$B$2*(ABS(D$13-$B17)/MIN(D$13,$B17))),40%) -> 0.91393119 | E17: =+IF(E$12<>$A17,99.9%,1)*MAX(EXP(-$B$2*(ABS(E$13-$B17)/MIN(E$13,$B17))),40%) -> 0.97044553 | F17: =+IF(F$12<>$A17,99.9%,1)*MAX(EXP(-$B$2*(ABS(F$13-$B17)/MIN(F$13,$B17))),40%) -> 1 | G17: =+IF(G$12<>$A17,99.9%,1)*MAX(EXP(-$B$2*(ABS(G$13-$B17)/MIN(G$13,$B17))),40%) -> 0.98511194 | H17: =+IF(H$12<>$A17,99.9%,1)*MAX(EXP(-$B$2*(ABS(H$13-$B17)/MIN(H$13,$B17))),40%) -> 0.95599748 | I17: =+IF(I$12<>$A17,99.9%,1)*MAX(EXP(-$B$2*(ABS(I$13-$B17)/MIN(I$13,$B17))),40%) -> 0.88692044 | J17: =+IF(J$12<>$A17,99.9%,1)*MAX(EXP(-$B$2*(ABS(J$13-$B17)/MIN(J$13,$B17))),40%) -> 0.82283466 | ... V17: =+IF(V$12<>$A17,99.9%,1)*MAX(EXP(-$B$2*(ABS(V$13-$B17)/MIN(V$13,$B17))),40%) -> 0.65638977 | X17: 1M | Y17: 2 | Z17: =+IF(C17*$Y$2>1,1,C17*$Y$2) -> 0.81058425 | AA17: =+IF(D17*$Y$2>1,1,D17*$Y$2) -> 0.91393119 | AB17: =+IF(E17*$Y$2>1,1,E17*$Y$2) -> 0.97044553 | AC17: 1 | AD17: =+IF(G17*$Y$2>1,1,G17*$Y$2) -> 0.98511194 | AE17: =+IF(H17*$Y$2>1,1,H17*$Y$2) -> 0.95599748 | AF17: =+IF(I17*$Y$2>1,1,I17*$Y$2) -> 0.88692044 | AG17: =+IF(J17*$Y$2>1,1,J17*$Y$2) -> 0.82283466 | AH17: =+IF(K17*$Y$2>1,1,K17*$Y$2) -> 0.76337949 | AI17: =+IF(L17*$Y$2>1,1,L17*$Y$2) -> 0.65704682 | AJ17: =+IF(M17*$Y$2>1,1,M17*$Y$2) -> 0.80977366 | AK17: =+IF(N17*$Y$2>1,1,N17*$Y$2) -> 0.91301725 | ... AS17: =+IF(V17*$Y$2>1,1,V17*$Y$2) -> 0.65638977
A18: 1M | B18: 3 | C18: =+IF(C$12<>$A18,99.9%,1)*MAX(EXP(-$B$2*(ABS(C$13-$B18)/MIN(C$13,$B18))),40%) -> 0.71892373 | D18: =+IF(D$12<>$A18,99.9%,1)*MAX(EXP(-$B$2*(ABS(D$13-$B18)/MIN(D$13,$B18))),40%) -> 0.86070798 | E18: =+IF(E$12<>$A18,99.9%,1)*MAX(EXP(-$B$2*(ABS(E$13-$B18)/MIN(E$13,$B18))),40%) -> 0.94176453 | F18: =+IF(F$12<>$A18,99.9%,1)*MAX(EXP(-$B$2*(ABS(F$13-$B18)/MIN(F$13,$B18))),40%) -> 0.98511194 | G18: =+IF(G$12<>$A18,99.9%,1)*MAX(EXP(-$B$2*(ABS(G$13-$B18)/MIN(G$13,$B18))),40%) -> 1 | H18: =+IF(H$12<>$A18,99.9%,1)*MAX(EXP(-$B$2*(ABS(H$13-$B18)/MIN(H$13,$B18))),40%) -> 0.98019867 | I18: =+IF(I$12<>$A18,99.9%,1)*MAX(EXP(-$B$2*(ABS(I$13-$B18)/MIN(I$13,$B18))),40%) -> 0.93239382 | J18: =+IF(J$12<>$A18,99.9%,1)*MAX(EXP(-$B$2*(ABS(J$13-$B18)/MIN(J$13,$B18))),40%) -> 0.88692044 | ... V18: =+IF(V$12<>$A18,99.9%,1)*MAX(EXP(-$B$2*(ABS(V$13-$B18)/MIN(V$13,$B18))),40%) -> 0.76261611 | X18: 1M | Y18: 3 | Z18: =+IF(C18*$Y$2>1,1,C18*$Y$2) -> 0.71892373 | AA18: =+IF(D18*$Y$2>1,1,D18*$Y$2) -> 0.86070798 | AB18: =+IF(E18*$Y$2>1,1,E18*$Y$2) -> 0.94176453 | AC18: =+IF(F18*$Y$2>1,1,F18*$Y$2) -> 0.98511194 | AD18: 1 | AE18: =+IF(H18*$Y$2>1,1,H18*$Y$2) -> 0.98019867 | AF18: =+IF(I18*$Y$2>1,1,I18*$Y$2) -> 0.93239382 | AG18: =+IF(J18*$Y$2>1,1,J18*$Y$2) -> 0.88692044 | AH18: =+IF(K18*$Y$2>1,1,K18*$Y$2) -> 0.84366482 | AI18: =+IF(L18*$Y$2>1,1,L18*$Y$2) -> 0.76337949 | AJ18: =+IF(M18*$Y$2>1,1,M18*$Y$2) -> 0.71820481 | AK18: =+IF(N18*$Y$2>1,1,N18*$Y$2) -> 0.85984727 | AL18: =+IF(O18*$Y$2>1,1,O18*$Y$2) -> 0.94082277 | ... AS18: =+IF(V18*$Y$2>1,1,V18*$Y$2) -> 0.76261611
A19: 1M | B19: 5 | C19: =+IF(C$12<>$A19,99.9%,1)*MAX(EXP(-$B$2*(ABS(C$13-$B19)/MIN(C$13,$B19))),40%) -> 0.56552544 | D19: =+IF(D$12<>$A19,99.9%,1)*MAX(EXP(-$B$2*(ABS(D$13-$B19)/MIN(D$13,$B19))),40%) -> 0.76337949 | E19: =+IF(E$12<>$A19,99.9%,1)*MAX(EXP(-$B$2*(ABS(E$13-$B19)/MIN(E$13,$B19))),40%) -> 0.88692044 | F19: =+IF(F$12<>$A19,99.9%,1)*MAX(EXP(-$B$2*(ABS(F$13-$B19)/MIN(F$13,$B19))),40%) -> 0.95599748 | G19: =+IF(G$12<>$A19,99.9%,1)*MAX(EXP(-$B$2*(ABS(G$13-$B19)/MIN(G$13,$B19))),40%) -> 0.98019867 | H19: =+IF(H$12<>$A19,99.9%,1)*MAX(EXP(-$B$2*(ABS(H$13-$B19)/MIN(H$13,$B19))),40%) -> 1 | I19: =+IF(I$12<>$A19,99.9%,1)*MAX(EXP(-$B$2*(ABS(I$13-$B19)/MIN(I$13,$B19))),40%) -> 0.97044553 | J19: =+IF(J$12<>$A19,99.9%,1)*MAX(EXP(-$B$2*(ABS(J$13-$B19)/MIN(J$13,$B19))),40%) -> 0.94176453 | ... V19: =+IF(V$12<>$A19,99.9%,1)*MAX(EXP(-$B$2*(ABS(V$13-$B19)/MIN(V$13,$B19))),40%) -> 0.85984727 | X19: 1M | Y19: 5 | Z19: =+IF(C19*$Y$2>1,1,C19*$Y$2) -> 0.56552544 | AA19: =+IF(D19*$Y$2>1,1,D19*$Y$2) -> 0.76337949 | AB19: =+IF(E19*$Y$2>1,1,E19*$Y$2) -> 0.88692044 | AC19: =+IF(F19*$Y$2>1,1,F19*$Y$2) -> 0.95599748 | AD19: =+IF(G19*$Y$2>1,1,G19*$Y$2) -> 0.98019867 | AE19: 1 | AF19: =+IF(I19*$Y$2>1,1,I19*$Y$2) -> 0.97044553 | AG19: =+IF(J19*$Y$2>1,1,J19*$Y$2) -> 0.94176453 | AH19: =+IF(K19*$Y$2>1,1,K19*$Y$2) -> 0.91393119 | AI19: =+IF(L19*$Y$2>1,1,L19*$Y$2) -> 0.86070798 | AJ19: =+IF(M19*$Y$2>1,1,M19*$Y$2) -> 0.56495991 | AK19: =+IF(N19*$Y$2>1,1,N19*$Y$2) -> 0.76261611 | AL19: =+IF(O19*$Y$2>1,1,O19*$Y$2) -> 0.88603352 | AM19: =+IF(P19*$Y$2>1,1,P19*$Y$2) -> 0.95504148 | ... AS19: =+IF(V19*$Y$2>1,1,V19*$Y$2) -> 0.85984727
A20: 1M | B20: 10 | C20: =+IF(C$12<>$A20,99.9%,1)*MAX(EXP(-$B$2*(ABS(C$13-$B20)/MIN(C$13,$B20))),40%) -> 0.4 | D20: =+IF(D$12<>$A20,99.9%,1)*MAX(EXP(-$B$2*(ABS(D$13-$B20)/MIN(D$13,$B20))),40%) -> 0.56552544 | E20: =+IF(E$12<>$A20,99.9%,1)*MAX(EXP(-$B$2*(ABS(E$13-$B20)/MIN(E$13,$B20))),40%) -> 0.76337949 | F20: =+IF(F$12<>$A20,99.9%,1)*MAX(EXP(-$B$2*(ABS(F$13-$B20)/MIN(F$13,$B20))),40%) -> 0.88692044 | G20: =+IF(G$12<>$A20,99.9%,1)*MAX(EXP(-$B$2*(ABS(G$13-$B20)/MIN(G$13,$B20))),40%) -> 0.93239382 | H20: =+IF(H$12<>$A20,99.9%,1)*MAX(EXP(-$B$2*(ABS(H$13-$B20)/MIN(H$13,$B20))),40%) -> 0.97044553 | I20: =+IF(I$12<>$A20,99.9%,1)*MAX(EXP(-$B$2*(ABS(I$13-$B20)/MIN(I$13,$B20))),40%) -> 1 | J20: =+IF(J$12<>$A20,99.9%,1)*MAX(EXP(-$B$2*(ABS(J$13-$B20)/MIN(J$13,$B20))),40%) -> 0.98511194 | ... V20: =+IF(V$12<>$A20,99.9%,1)*MAX(EXP(-$B$2*(ABS(V$13-$B20)/MIN(V$13,$B20))),40%) -> 0.94082277 | X20: 1M | Y20: 10 | Z20: =+IF(C20*$Y$2>1,1,C20*$Y$2) -> 0.4 | AA20: =+IF(D20*$Y$2>1,1,D20*$Y$2) -> 0.56552544 | AB20: =+IF(E20*$Y$2>1,1,E20*$Y$2) -> 0.76337949 | AC20: =+IF(F20*$Y$2>1,1,F20*$Y$2) -> 0.88692044 | AD20: =+IF(G20*$Y$2>1,1,G20*$Y$2) -> 0.93239382 | AE20: =+IF(H20*$Y$2>1,1,H20*$Y$2) -> 0.97044553 | AF20: 1 | AG20: =+IF(J20*$Y$2>1,1,J20*$Y$2) -> 0.98511194 | AH20: =+IF(K20*$Y$2>1,1,K20*$Y$2) -> 0.97044553 | AI20: =+IF(L20*$Y$2>1,1,L20*$Y$2) -> 0.94176453 | AJ20: =+IF(M20*$Y$2>1,1,M20*$Y$2) -> 0.3996 | AK20: =+IF(N20*$Y$2>1,1,N20*$Y$2) -> 0.56495991 | AL20: =+IF(O20*$Y$2>1,1,O20*$Y$2) -> 0.76261611 | AM20: =+IF(P20*$Y$2>1,1,P20*$Y$2) -> 0.88603352 | AN20: =+IF(Q20*$Y$2>1,1,Q20*$Y$2) -> 0.93146143 | ... AS20: =+IF(V20*$Y$2>1,1,V20*$Y$2) -> 0.94082277
A21: 1M | B21: 15 | C21: =+IF(C$12<>$A21,99.9%,1)*MAX(EXP(-$B$2*(ABS(C$13-$B21)/MIN(C$13,$B21))),40%) -> 0.4 | D21: =+IF(D$12<>$A21,99.9%,1)*MAX(EXP(-$B$2*(ABS(D$13-$B21)/MIN(D$13,$B21))),40%) -> 0.41895155 | E21: =+IF(E$12<>$A21,99.9%,1)*MAX(EXP(-$B$2*(ABS(E$13-$B21)/MIN(E$13,$B21))),40%) -> 0.65704682 | F21: =+IF(F$12<>$A21,99.9%,1)*MAX(EXP(-$B$2*(ABS(F$13-$B21)/MIN(F$13,$B21))),40%) -> 0.82283466 | G21: =+IF(G$12<>$A21,99.9%,1)*MAX(EXP(-$B$2*(ABS(G$13-$B21)/MIN(G$13,$B21))),40%) -> 0.88692044 | H21: =+IF(H$12<>$A21,99.9%,1)*MAX(EXP(-$B$2*(ABS(H$13-$B21)/MIN(H$13,$B21))),40%) -> 0.94176453 | I21: =+IF(I$12<>$A21,99.9%,1)*MAX(EXP(-$B$2*(ABS(I$13-$B21)/MIN(I$13,$B21))),40%) -> 0.98511194 | J21: =+IF(J$12<>$A21,99.9%,1)*MAX(EXP(-$B$2*(ABS(J$13-$B21)/MIN(J$13,$B21))),40%) -> 1 | ... V21: =+IF(V$12<>$A21,99.9%,1)*MAX(EXP(-$B$2*(ABS(V$13-$B21)/MIN(V$13,$B21))),40%) -> 0.96947509 | X21: 1M | Y21: 15 | Z21: =+IF(C21*$Y$2>1,1,C21*$Y$2) -> 0.4 | AA21: =+IF(D21*$Y$2>1,1,D21*$Y$2) -> 0.41895155 | AB21: =+IF(E21*$Y$2>1,1,E21*$Y$2) -> 0.65704682 | AC21: =+IF(F21*$Y$2>1,1,F21*$Y$2) -> 0.82283466 | AD21: =+IF(G21*$Y$2>1,1,G21*$Y$2) -> 0.88692044 | AE21: =+IF(H21*$Y$2>1,1,H21*$Y$2) -> 0.94176453 | AF21: =+IF(I21*$Y$2>1,1,I21*$Y$2) -> 0.98511194 | AG21: 1 | AH21: =+IF(K21*$Y$2>1,1,K21*$Y$2) -> 0.99004983 | AI21: =+IF(L21*$Y$2>1,1,L21*$Y$2) -> 0.97044553 | AJ21: =+IF(M21*$Y$2>1,1,M21*$Y$2) -> 0.3996 | AK21: =+IF(N21*$Y$2>1,1,N21*$Y$2) -> 0.4185326 | AL21: =+IF(O21*$Y$2>1,1,O21*$Y$2) -> 0.65638977 | AM21: =+IF(P21*$Y$2>1,1,P21*$Y$2) -> 0.82201182 | AN21: =+IF(Q21*$Y$2>1,1,Q21*$Y$2) -> 0.88603352 | AO21: =+IF(R21*$Y$2>1,1,R21*$Y$2) -> 0.94082277 | ... AS21: =+IF(V21*$Y$2>1,1,V21*$Y$2) -> 0.96947509
A22: 1M | B22: 20 | C22: =+IF(C$12<>$A22,99.9%,1)*MAX(EXP(-$B$2*(ABS(C$13-$B22)/MIN(C$13,$B22))),40%) -> 0.4 | D22: =+IF(D$12<>$A22,99.9%,1)*MAX(EXP(-$B$2*(ABS(D$13-$B22)/MIN(D$13,$B22))),40%) -> 0.4 | E22: =+IF(E$12<>$A22,99.9%,1)*MAX(EXP(-$B$2*(ABS(E$13-$B22)/MIN(E$13,$B22))),40%) -> 0.56552544 | F22: =+IF(F$12<>$A22,99.9%,1)*MAX(EXP(-$B$2*(ABS(F$13-$B22)/MIN(F$13,$B22))),40%) -> 0.76337949 | G22: =+IF(G$12<>$A22,99.9%,1)*MAX(EXP(-$B$2*(ABS(G$13-$B22)/MIN(G$13,$B22))),40%) -> 0.84366482 | H22: =+IF(H$12<>$A22,99.9%,1)*MAX(EXP(-$B$2*(ABS(H$13-$B22)/MIN(H$13,$B22))),40%) -> 0.91393119 | I22: =+IF(I$12<>$A22,99.9%,1)*MAX(EXP(-$B$2*(ABS(I$13-$B22)/MIN(I$13,$B22))),40%) -> 0.97044553 | J22: =+IF(J$12<>$A22,99.9%,1)*MAX(EXP(-$B$2*(ABS(J$13-$B22)/MIN(J$13,$B22))),40%) -> 0.99004983 | ... V22: =+IF(V$12<>$A22,99.9%,1)*MAX(EXP(-$B$2*(ABS(V$13-$B22)/MIN(V$13,$B22))),40%) -> 0.98412683 | X22: 1M | Y22: 20 | Z22: =+IF(C22*$Y$2>1,1,C22*$Y$2) -> 0.4 | AA22: =+IF(D22*$Y$2>1,1,D22*$Y$2) -> 0.4 | AB22: =+IF(E22*$Y$2>1,1,E22*$Y$2) -> 0.56552544 | AC22: =+IF(F22*$Y$2>1,1,F22*$Y$2) -> 0.76337949 | AD22: =+IF(G22*$Y$2>1,1,G22*$Y$2) -> 0.84366482 | AE22: =+IF(H22*$Y$2>1,1,H22*$Y$2) -> 0.91393119 | AF22: =+IF(I22*$Y$2>1,1,I22*$Y$2) -> 0.97044553 | AG22: =+IF(J22*$Y$2>1,1,J22*$Y$2) -> 0.99004983 | AH22: 1 | AI22: =+IF(L22*$Y$2>1,1,L22*$Y$2) -> 0.98511194 | AJ22: =+IF(M22*$Y$2>1,1,M22*$Y$2) -> 0.3996 | AK22: =+IF(N22*$Y$2>1,1,N22*$Y$2) -> 0.3996 | AL22: =+IF(O22*$Y$2>1,1,O22*$Y$2) -> 0.56495991 | AM22: =+IF(P22*$Y$2>1,1,P22*$Y$2) -> 0.76261611 | AN22: =+IF(Q22*$Y$2>1,1,Q22*$Y$2) -> 0.84282115 | AO22: =+IF(R22*$Y$2>1,1,R22*$Y$2) -> 0.91301725 | AP22: =+IF(S22*$Y$2>1,1,S22*$Y$2) -> 0.96947509 | ... AS22: =+IF(V22*$Y$2>1,1,V22*$Y$2) -> 0.98412683
A23: 1M | B23: 30 | C23: =+IF(C$12<>$A23,99.9%,1)*MAX(EXP(-$B$2*(ABS(C$13-$B23)/MIN(C$13,$B23))),40%) -> 0.4 | D23: =+IF(D$12<>$A23,99.9%,1)*MAX(EXP(-$B$2*(ABS(D$13-$B23)/MIN(D$13,$B23))),40%) -> 0.4 | E23: =+IF(E$12<>$A23,99.9%,1)*MAX(EXP(-$B$2*(ABS(E$13-$B23)/MIN(E$13,$B23))),40%) -> 0.41895155 | F23: =+IF(F$12<>$A23,99.9%,1)*MAX(EXP(-$B$2*(ABS(F$13-$B23)/MIN(F$13,$B23))),40%) -> 0.65704682 | G23: =+IF(G$12<>$A23,99.9%,1)*MAX(EXP(-$B$2*(ABS(G$13-$B23)/MIN(G$13,$B23))),40%) -> 0.76337949 | H23: =+IF(H$12<>$A23,99.9%,1)*MAX(EXP(-$B$2*(ABS(H$13-$B23)/MIN(H$13,$B23))),40%) -> 0.86070798 | I23: =+IF(I$12<>$A23,99.9%,1)*MAX(EXP(-$B$2*(ABS(I$13-$B23)/MIN(I$13,$B23))),40%) -> 0.94176453 | J23: =+IF(J$12<>$A23,99.9%,1)*MAX(EXP(-$B$2*(ABS(J$13-$B23)/MIN(J$13,$B23))),40%) -> 0.97044553 | ... V23: =+IF(V$12<>$A23,99.9%,1)*MAX(EXP(-$B$2*(ABS(V$13-$B23)/MIN(V$13,$B23))),40%) -> 0.999 | X23: 1M | Y23: 30 | Z23: =+IF(C23*$Y$2>1,1,C23*$Y$2) -> 0.4 | AA23: =+IF(D23*$Y$2>1,1,D23*$Y$2) -> 0.4 | AB23: =+IF(E23*$Y$2>1,1,E23*$Y$2) -> 0.41895155 | AC23: =+IF(F23*$Y$2>1,1,F23*$Y$2) -> 0.65704682 | AD23: =+IF(G23*$Y$2>1,1,G23*$Y$2) -> 0.76337949 | AE23: =+IF(H23*$Y$2>1,1,H23*$Y$2) -> 0.86070798 | AF23: =+IF(I23*$Y$2>1,1,I23*$Y$2) -> 0.94176453 | AG23: =+IF(J23*$Y$2>1,1,J23*$Y$2) -> 0.97044553 | AH23: =+IF(K23*$Y$2>1,1,K23*$Y$2) -> 0.98511194 | AI23: 1 | AJ23: =+IF(M23*$Y$2>1,1,M23*$Y$2) -> 0.3996 | AK23: =+IF(N23*$Y$2>1,1,N23*$Y$2) -> 0.3996 | AL23: =+IF(O23*$Y$2>1,1,O23*$Y$2) -> 0.4185326 | AM23: =+IF(P23*$Y$2>1,1,P23*$Y$2) -> 0.65638977 | AN23: =+IF(Q23*$Y$2>1,1,Q23*$Y$2) -> 0.76261611 | AO23: =+IF(R23*$Y$2>1,1,R23*$Y$2) -> 0.85984727 | AP23: =+IF(S23*$Y$2>1,1,S23*$Y$2) -> 0.94082277 | AQ23: =+IF(T23*$Y$2>1,1,T23*$Y$2) -> 0.96947509 | ... AS23: =+IF(V23*$Y$2>1,1,V23*$Y$2) -> 0.999
A24: 3M | B24: 0.25 | C24: =+IF(C$12<>$A24,99.9%,1)*MAX(EXP(-$B$2*(ABS(C$13-$B24)/MIN(C$13,$B24))),40%) -> 0.999 | D24: =+IF(D$12<>$A24,99.9%,1)*MAX(EXP(-$B$2*(ABS(D$13-$B24)/MIN(D$13,$B24))),40%) -> 0.96947509 | E24: =+IF(E$12<>$A24,99.9%,1)*MAX(EXP(-$B$2*(ABS(E$13-$B24)/MIN(E$13,$B24))),40%) -> 0.91301725 | F24: =+IF(F$12<>$A24,99.9%,1)*MAX(EXP(-$B$2*(ABS(F$13-$B24)/MIN(F$13,$B24))),40%) -> 0.80977366 | G24: =+IF(G$12<>$A24,99.9%,1)*MAX(EXP(-$B$2*(ABS(G$13-$B24)/MIN(G$13,$B24))),40%) -> 0.71820481 | H24: =+IF(H$12<>$A24,99.9%,1)*MAX(EXP(-$B$2*(ABS(H$13-$B24)/MIN(H$13,$B24))),40%) -> 0.56495991 | I24: =+IF(I$12<>$A24,99.9%,1)*MAX(EXP(-$B$2*(ABS(I$13-$B24)/MIN(I$13,$B24))),40%) -> 0.3996 | J24: =+IF(J$12<>$A24,99.9%,1)*MAX(EXP(-$B$2*(ABS(J$13-$B24)/MIN(J$13,$B24))),40%) -> 0.3996 | ... V24: =+IF(V$12<>$A24,99.9%,1)*MAX(EXP(-$B$2*(ABS(V$13-$B24)/MIN(V$13,$B24))),40%) -> 0.4 | X24: 3M | Y24: 0.25 | Z24: =+IF(C24*$Y$2>1,1,C24*$Y$2) -> 0.999 | AA24: =+IF(D24*$Y$2>1,1,D24*$Y$2) -> 0.96947509 | AB24: =+IF(E24*$Y$2>1,1,E24*$Y$2) -> 0.91301725 | AC24: =+IF(F24*$Y$2>1,1,F24*$Y$2) -> 0.80977366 | AD24: =+IF(G24*$Y$2>1,1,G24*$Y$2) -> 0.71820481 | AE24: =+IF(H24*$Y$2>1,1,H24*$Y$2) -> 0.56495991 | AF24: =+IF(I24*$Y$2>1,1,I24*$Y$2) -> 0.3996 | AG24: =+IF(J24*$Y$2>1,1,J24*$Y$2) -> 0.3996 | ... AI24: =+IF(L24*$Y$2>1,1,L24*$Y$2) -> 0.3996 | AJ24: 1 | AK24: =+IF(N24*$Y$2>1,1,N24*$Y$2) -> 0.97044553 | AL24: =+IF(O24*$Y$2>1,1,O24*$Y$2) -> 0.91393119 | AM24: =+IF(P24*$Y$2>1,1,P24*$Y$2) -> 0.81058425 | AN24: =+IF(Q24*$Y$2>1,1,Q24*$Y$2) -> 0.71892373 | AO24: =+IF(R24*$Y$2>1,1,R24*$Y$2) -> 0.56552544 | AP24: =+IF(S24*$Y$2>1,1,S24*$Y$2) -> 0.4 | AQ24: =+IF(T24*$Y$2>1,1,T24*$Y$2) -> 0.4 | AR24: =+IF(U24*$Y$2>1,1,U24*$Y$2) -> 0.4 | AS24: =+IF(V24*$Y$2>1,1,V24*$Y$2) -> 0.4
A25: 3M | B25: 0.5 | C25: =+IF(C$12<>$A25,99.9%,1)*MAX(EXP(-$B$2*(ABS(C$13-$B25)/MIN(C$13,$B25))),40%) -> 0.96947509 | D25: =+IF(D$12<>$A25,99.9%,1)*MAX(EXP(-$B$2*(ABS(D$13-$B25)/MIN(D$13,$B25))),40%) -> 0.999 | E25: =+IF(E$12<>$A25,99.9%,1)*MAX(EXP(-$B$2*(ABS(E$13-$B25)/MIN(E$13,$B25))),40%) -> 0.96947509 | F25: =+IF(F$12<>$A25,99.9%,1)*MAX(EXP(-$B$2*(ABS(F$13-$B25)/MIN(F$13,$B25))),40%) -> 0.91301725 | G25: =+IF(G$12<>$A25,99.9%,1)*MAX(EXP(-$B$2*(ABS(G$13-$B25)/MIN(G$13,$B25))),40%) -> 0.85984727 | H25: =+IF(H$12<>$A25,99.9%,1)*MAX(EXP(-$B$2*(ABS(H$13-$B25)/MIN(H$13,$B25))),40%) -> 0.76261611 | I25: =+IF(I$12<>$A25,99.9%,1)*MAX(EXP(-$B$2*(ABS(I$13-$B25)/MIN(I$13,$B25))),40%) -> 0.56495991 | J25: =+IF(J$12<>$A25,99.9%,1)*MAX(EXP(-$B$2*(ABS(J$13-$B25)/MIN(J$13,$B25))),40%) -> 0.4185326 | ... V25: =+IF(V$12<>$A25,99.9%,1)*MAX(EXP(-$B$2*(ABS(V$13-$B25)/MIN(V$13,$B25))),40%) -> 0.4 | X25: 3M | Y25: 0.5 | Z25: =+IF(C25*$Y$2>1,1,C25*$Y$2) -> 0.96947509 | AA25: =+IF(D25*$Y$2>1,1,D25*$Y$2) -> 0.999 | AB25: =+IF(E25*$Y$2>1,1,E25*$Y$2) -> 0.96947509 | AC25: =+IF(F25*$Y$2>1,1,F25*$Y$2) -> 0.91301725 | AD25: =+IF(G25*$Y$2>1,1,G25*$Y$2) -> 0.85984727 | AE25: =+IF(H25*$Y$2>1,1,H25*$Y$2) -> 0.76261611 | AF25: =+IF(I25*$Y$2>1,1,I25*$Y$2) -> 0.56495991 | AG25: =+IF(J25*$Y$2>1,1,J25*$Y$2) -> 0.4185326 | ... AJ25: =+IF(M25*$Y$2>1,1,M25*$Y$2) -> 0.97044553 | AK25: 1 | AL25: =+IF(O25*$Y$2>1,1,O25*$Y$2) -> 0.97044553 | AM25: =+IF(P25*$Y$2>1,1,P25*$Y$2) -> 0.91393119 | AN25: =+IF(Q25*$Y$2>1,1,Q25*$Y$2) -> 0.86070798 | AO25: =+IF(R25*$Y$2>1,1,R25*$Y$2) -> 0.76337949 | AP25: =+IF(S25*$Y$2>1,1,S25*$Y$2) -> 0.56552544 | AQ25: =+IF(T25*$Y$2>1,1,T25*$Y$2) -> 0.41895155 | AR25: =+IF(U25*$Y$2>1,1,U25*$Y$2) -> 0.4 | AS25: =+IF(V25*$Y$2>1,1,V25*$Y$2) -> 0.4
A26: 3M | B26: 1 | C26: =+IF(C$12<>$A26,99.9%,1)*MAX(EXP(-$B$2*(ABS(C$13-$B26)/MIN(C$13,$B26))),40%) -> 0.91301725 | D26: =+IF(D$12<>$A26,99.9%,1)*MAX(EXP(-$B$2*(ABS(D$13-$B26)/MIN(D$13,$B26))),40%) -> 0.96947509 | E26: =+IF(E$12<>$A26,99.9%,1)*MAX(EXP(-$B$2*(ABS(E$13-$B26)/MIN(E$13,$B26))),40%) -> 0.999 | F26: =+IF(F$12<>$A26,99.9%,1)*MAX(EXP(-$B$2*(ABS(F$13-$B26)/MIN(F$13,$B26))),40%) -> 0.96947509 | G26: =+IF(G$12<>$A26,99.9%,1)*MAX(EXP(-$B$2*(ABS(G$13-$B26)/MIN(G$13,$B26))),40%) -> 0.94082277 | H26: =+IF(H$12<>$A26,99.9%,1)*MAX(EXP(-$B$2*(ABS(H$13-$B26)/MIN(H$13,$B26))),40%) -> 0.88603352 | I26: =+IF(I$12<>$A26,99.9%,1)*MAX(EXP(-$B$2*(ABS(I$13-$B26)/MIN(I$13,$B26))),40%) -> 0.76261611 | J26: =+IF(J$12<>$A26,99.9%,1)*MAX(EXP(-$B$2*(ABS(J$13-$B26)/MIN(J$13,$B26))),40%) -> 0.65638977 | ... V26: =+IF(V$12<>$A26,99.9%,1)*MAX(EXP(-$B$2*(ABS(V$13-$B26)/MIN(V$13,$B26))),40%) -> 0.41895155 | X26: 3M | Y26: 1 | Z26: =+IF(C26*$Y$2>1,1,C26*$Y$2) -> 0.91301725 | AA26: =+IF(D26*$Y$2>1,1,D26*$Y$2) -> 0.96947509 | AB26: =+IF(E26*$Y$2>1,1,E26*$Y$2) -> 0.999 | AC26: =+IF(F26*$Y$2>1,1,F26*$Y$2) -> 0.96947509 | AD26: =+IF(G26*$Y$2>1,1,G26*$Y$2) -> 0.94082277 | AE26: =+IF(H26*$Y$2>1,1,H26*$Y$2) -> 0.88603352 | AF26: =+IF(I26*$Y$2>1,1,I26*$Y$2) -> 0.76261611 | AG26: =+IF(J26*$Y$2>1,1,J26*$Y$2) -> 0.65638977 | ... AK26: =+IF(N26*$Y$2>1,1,N26*$Y$2) -> 0.97044553 | AL26: 1 | AM26: =+IF(P26*$Y$2>1,1,P26*$Y$2) -> 0.97044553 | AN26: =+IF(Q26*$Y$2>1,1,Q26*$Y$2) -> 0.94176453 | AO26: =+IF(R26*$Y$2>1,1,R26*$Y$2) -> 0.88692044 | AP26: =+IF(S26*$Y$2>1,1,S26*$Y$2) -> 0.76337949 | AQ26: =+IF(T26*$Y$2>1,1,T26*$Y$2) -> 0.65704682 | AR26: =+IF(U26*$Y$2>1,1,U26*$Y$2) -> 0.56552544 | AS26: =+IF(V26*$Y$2>1,1,V26*$Y$2) -> 0.41895155
A27: 3M | B27: 2 | C27: =+IF(C$12<>$A27,99.9%,1)*MAX(EXP(-$B$2*(ABS(C$13-$B27)/MIN(C$13,$B27))),40%) -> 0.80977366 | D27: =+IF(D$12<>$A27,99.9%,1)*MAX(EXP(-$B$2*(ABS(D$13-$B27)/MIN(D$13,$B27))),40%) -> 0.91301725 | E27: =+IF(E$12<>$A27,99.9%,1)*MAX(EXP(-$B$2*(ABS(E$13-$B27)/MIN(E$13,$B27))),40%) -> 0.96947509 | F27: =+IF(F$12<>$A27,99.9%,1)*MAX(EXP(-$B$2*(ABS(F$13-$B27)/MIN(F$13,$B27))),40%) -> 0.999 | G27: =+IF(G$12<>$A27,99.9%,1)*MAX(EXP(-$B$2*(ABS(G$13-$B27)/MIN(G$13,$B27))),40%) -> 0.98412683 | H27: =+IF(H$12<>$A27,99.9%,1)*MAX(EXP(-$B$2*(ABS(H$13-$B27)/MIN(H$13,$B27))),40%) -> 0.95504148 | I27: =+IF(I$12<>$A27,99.9%,1)*MAX(EXP(-$B$2*(ABS(I$13-$B27)/MIN(I$13,$B27))),40%) -> 0.88603352 | J27: =+IF(J$12<>$A27,99.9%,1)*MAX(EXP(-$B$2*(ABS(J$13-$B27)/MIN(J$13,$B27))),40%) -> 0.82201182 | ... V27: =+IF(V$12<>$A27,99.9%,1)*MAX(EXP(-$B$2*(ABS(V$13-$B27)/MIN(V$13,$B27))),40%) -> 0.65704682 | X27: 3M | Y27: 2 | Z27: =+IF(C27*$Y$2>1,1,C27*$Y$2) -> 0.80977366 | AA27: =+IF(D27*$Y$2>1,1,D27*$Y$2) -> 0.91301725 | AB27: =+IF(E27*$Y$2>1,1,E27*$Y$2) -> 0.96947509 | AC27: =+IF(F27*$Y$2>1,1,F27*$Y$2) -> 0.999 | AD27: =+IF(G27*$Y$2>1,1,G27*$Y$2) -> 0.98412683 | AE27: =+IF(H27*$Y$2>1,1,H27*$Y$2) -> 0.95504148 | AF27: =+IF(I27*$Y$2>1,1,I27*$Y$2) -> 0.88603352 | AG27: =+IF(J27*$Y$2>1,1,J27*$Y$2) -> 0.82201182 | ... AL27: =+IF(O27*$Y$2>1,1,O27*$Y$2) -> 0.97044553 | AM27: 1 | AN27: =+IF(Q27*$Y$2>1,1,Q27*$Y$2) -> 0.98511194 | AO27: =+IF(R27*$Y$2>1,1,R27*$Y$2) -> 0.95599748 | AP27: =+IF(S27*$Y$2>1,1,S27*$Y$2) -> 0.88692044 | AQ27: =+IF(T27*$Y$2>1,1,T27*$Y$2) -> 0.82283466 | AR27: =+IF(U27*$Y$2>1,1,U27*$Y$2) -> 0.76337949 | AS27: =+IF(V27*$Y$2>1,1,V27*$Y$2) -> 0.65704682
A28: 3M | B28: 3 | C28: =+IF(C$12<>$A28,99.9%,1)*MAX(EXP(-$B$2*(ABS(C$13-$B28)/MIN(C$13,$B28))),40%) -> 0.71820481 | D28: =+IF(D$12<>$A28,99.9%,1)*MAX(EXP(-$B$2*(ABS(D$13-$B28)/MIN(D$13,$B28))),40%) -> 0.85984727 | E28: =+IF(E$12<>$A28,99.9%,1)*MAX(EXP(-$B$2*(ABS(E$13-$B28)/MIN(E$13,$B28))),40%) -> 0.94082277 | F28: =+IF(F$12<>$A28,99.9%,1)*MAX(EXP(-$B$2*(ABS(F$13-$B28)/MIN(F$13,$B28))),40%) -> 0.98412683 | G28: =+IF(G$12<>$A28,99.9%,1)*MAX(EXP(-$B$2*(ABS(G$13-$B28)/MIN(G$13,$B28))),40%) -> 0.999 | H28: =+IF(H$12<>$A28,99.9%,1)*MAX(EXP(-$B$2*(ABS(H$13-$B28)/MIN(H$13,$B28))),40%) -> 0.97921847 | I28: =+IF(I$12<>$A28,99.9%,1)*MAX(EXP(-$B$2*(ABS(I$13-$B28)/MIN(I$13,$B28))),40%) -> 0.93146143 | J28: =+IF(J$12<>$A28,99.9%,1)*MAX(EXP(-$B$2*(ABS(J$13-$B28)/MIN(J$13,$B28))),40%) -> 0.88603352 | ... V28: =+IF(V$12<>$A28,99.9%,1)*MAX(EXP(-$B$2*(ABS(V$13-$B28)/MIN(V$13,$B28))),40%) -> 0.76337949 | X28: 3M | Y28: 3 | Z28: =+IF(C28*$Y$2>1,1,C28*$Y$2) -> 0.71820481 | AA28: =+IF(D28*$Y$2>1,1,D28*$Y$2) -> 0.85984727 | AB28: =+IF(E28*$Y$2>1,1,E28*$Y$2) -> 0.94082277 | AC28: =+IF(F28*$Y$2>1,1,F28*$Y$2) -> 0.98412683 | AD28: =+IF(G28*$Y$2>1,1,G28*$Y$2) -> 0.999 | AE28: =+IF(H28*$Y$2>1,1,H28*$Y$2) -> 0.97921847 | AF28: =+IF(I28*$Y$2>1,1,I28*$Y$2) -> 0.93146143 | AG28: =+IF(J28*$Y$2>1,1,J28*$Y$2) -> 0.88603352 | ... AM28: =+IF(P28*$Y$2>1,1,P28*$Y$2) -> 0.98511194 | AN28: 1 | AO28: =+IF(R28*$Y$2>1,1,R28*$Y$2) -> 0.98019867 | AP28: =+IF(S28*$Y$2>1,1,S28*$Y$2) -> 0.93239382 | AQ28: =+IF(T28*$Y$2>1,1,T28*$Y$2) -> 0.88692044 | AR28: =+IF(U28*$Y$2>1,1,U28*$Y$2) -> 0.84366482 | AS28: =+IF(V28*$Y$2>1,1,V28*$Y$2) -> 0.76337949
A29: 3M | B29: 5 | C29: =+IF(C$12<>$A29,99.9%,1)*MAX(EXP(-$B$2*(ABS(C$13-$B29)/MIN(C$13,$B29))),40%) -> 0.56495991 | D29: =+IF(D$12<>$A29,99.9%,1)*MAX(EXP(-$B$2*(ABS(D$13-$B29)/MIN(D$13,$B29))),40%) -> 0.76261611 | E29: =+IF(E$12<>$A29,99.9%,1)*MAX(EXP(-$B$2*(ABS(E$13-$B29)/MIN(E$13,$B29))),40%) -> 0.88603352 | F29: =+IF(F$12<>$A29,99.9%,1)*MAX(EXP(-$B$2*(ABS(F$13-$B29)/MIN(F$13,$B29))),40%) -> 0.95504148 | G29: =+IF(G$12<>$A29,99.9%,1)*MAX(EXP(-$B$2*(ABS(G$13-$B29)/MIN(G$13,$B29))),40%) -> 0.97921847 | H29: =+IF(H$12<>$A29,99.9%,1)*MAX(EXP(-$B$2*(ABS(H$13-$B29)/MIN(H$13,$B29))),40%) -> 0.999 | I29: =+IF(I$12<>$A29,99.9%,1)*MAX(EXP(-$B$2*(ABS(I$13-$B29)/MIN(I$13,$B29))),40%) -> 0.96947509 | J29: =+IF(J$12<>$A29,99.9%,1)*MAX(EXP(-$B$2*(ABS(J$13-$B29)/MIN(J$13,$B29))),40%) -> 0.94082277 | ... V29: =+IF(V$12<>$A29,99.9%,1)*MAX(EXP(-$B$2*(ABS(V$13-$B29)/MIN(V$13,$B29))),40%) -> 0.86070798 | X29: 3M | Y29: 5 | Z29: =+IF(C29*$Y$2>1,1,C29*$Y$2) -> 0.56495991 | AA29: =+IF(D29*$Y$2>1,1,D29*$Y$2) -> 0.76261611 | AB29: =+IF(E29*$Y$2>1,1,E29*$Y$2) -> 0.88603352 | AC29: =+IF(F29*$Y$2>1,1,F29*$Y$2) -> 0.95504148 | AD29: =+IF(G29*$Y$2>1,1,G29*$Y$2) -> 0.97921847 | AE29: =+IF(H29*$Y$2>1,1,H29*$Y$2) -> 0.999 | AF29: =+IF(I29*$Y$2>1,1,I29*$Y$2) -> 0.96947509 | AG29: =+IF(J29*$Y$2>1,1,J29*$Y$2) -> 0.94082277 | ... AN29: =+IF(Q29*$Y$2>1,1,Q29*$Y$2) -> 0.98019867 | AO29: 1 | AP29: =+IF(S29*$Y$2>1,1,S29*$Y$2) -> 0.97044553 | AQ29: =+IF(T29*$Y$2>1,1,T29*$Y$2) -> 0.94176453 | AR29: =+IF(U29*$Y$2>1,1,U29*$Y$2) -> 0.91393119 | AS29: =+IF(V29*$Y$2>1,1,V29*$Y$2) -> 0.86070798
A30: 3M | B30: 10 | C30: =+IF(C$12<>$A30,99.9%,1)*MAX(EXP(-$B$2*(ABS(C$13-$B30)/MIN(C$13,$B30))),40%) -> 0.3996 | D30: =+IF(D$12<>$A30,99.9%,1)*MAX(EXP(-$B$2*(ABS(D$13-$B30)/MIN(D$13,$B30))),40%) -> 0.56495991 | E30: =+IF(E$12<>$A30,99.9%,1)*MAX(EXP(-$B$2*(ABS(E$13-$B30)/MIN(E$13,$B30))),40%) -> 0.76261611 | F30: =+IF(F$12<>$A30,99.9%,1)*MAX(EXP(-$B$2*(ABS(F$13-$B30)/MIN(F$13,$B30))),40%) -> 0.88603352 | G30: =+IF(G$12<>$A30,99.9%,1)*MAX(EXP(-$B$2*(ABS(G$13-$B30)/MIN(G$13,$B30))),40%) -> 0.93146143 | H30: =+IF(H$12<>$A30,99.9%,1)*MAX(EXP(-$B$2*(ABS(H$13-$B30)/MIN(H$13,$B30))),40%) -> 0.96947509 | I30: =+IF(I$12<>$A30,99.9%,1)*MAX(EXP(-$B$2*(ABS(I$13-$B30)/MIN(I$13,$B30))),40%) -> 0.999 | J30: =+IF(J$12<>$A30,99.9%,1)*MAX(EXP(-$B$2*(ABS(J$13-$B30)/MIN(J$13,$B30))),40%) -> 0.98412683 | ... V30: =+IF(V$12<>$A30,99.9%,1)*MAX(EXP(-$B$2*(ABS(V$13-$B30)/MIN(V$13,$B30))),40%) -> 0.94176453 | X30: 3M | Y30: 10 | Z30: =+IF(C30*$Y$2>1,1,C30*$Y$2) -> 0.3996 | AA30: =+IF(D30*$Y$2>1,1,D30*$Y$2) -> 0.56495991 | AB30: =+IF(E30*$Y$2>1,1,E30*$Y$2) -> 0.76261611 | AC30: =+IF(F30*$Y$2>1,1,F30*$Y$2) -> 0.88603352 | AD30: =+IF(G30*$Y$2>1,1,G30*$Y$2) -> 0.93146143 | AE30: =+IF(H30*$Y$2>1,1,H30*$Y$2) -> 0.96947509 | AF30: =+IF(I30*$Y$2>1,1,I30*$Y$2) -> 0.999 | AG30: =+IF(J30*$Y$2>1,1,J30*$Y$2) -> 0.98412683 | ... AO30: =+IF(R30*$Y$2>1,1,R30*$Y$2) -> 0.97044553 | AP30: 1 | AQ30: =+IF(T30*$Y$2>1,1,T30*$Y$2) -> 0.98511194 | AR30: =+IF(U30*$Y$2>1,1,U30*$Y$2) -> 0.97044553 | AS30: =+IF(V30*$Y$2>1,1,V30*$Y$2) -> 0.94176453
A31: 3M | B31: 15 | C31: =+IF(C$12<>$A31,99.9%,1)*MAX(EXP(-$B$2*(ABS(C$13-$B31)/MIN(C$13,$B31))),40%) -> 0.3996 | D31: =+IF(D$12<>$A31,99.9%,1)*MAX(EXP(-$B$2*(ABS(D$13-$B31)/MIN(D$13,$B31))),40%) -> 0.4185326 | E31: =+IF(E$12<>$A31,99.9%,1)*MAX(EXP(-$B$2*(ABS(E$13-$B31)/MIN(E$13,$B31))),40%) -> 0.65638977 | F31: =+IF(F$12<>$A31,99.9%,1)*MAX(EXP(-$B$2*(ABS(F$13-$B31)/MIN(F$13,$B31))),40%) -> 0.82201182 | G31: =+IF(G$12<>$A31,99.9%,1)*MAX(EXP(-$B$2*(ABS(G$13-$B31)/MIN(G$13,$B31))),40%) -> 0.88603352 | H31: =+IF(H$12<>$A31,99.9%,1)*MAX(EXP(-$B$2*(ABS(H$13-$B31)/MIN(H$13,$B31))),40%) -> 0.94082277 | I31: =+IF(I$12<>$A31,99.9%,1)*MAX(EXP(-$B$2*(ABS(I$13-$B31)/MIN(I$13,$B31))),40%) -> 0.98412683 | J31: =+IF(J$12<>$A31,99.9%,1)*MAX(EXP(-$B$2*(ABS(J$13-$B31)/MIN(J$13,$B31))),40%) -> 0.999 | ... V31: =+IF(V$12<>$A31,99.9%,1)*MAX(EXP(-$B$2*(ABS(V$13-$B31)/MIN(V$13,$B31))),40%) -> 0.97044553 | X31: 3M | Y31: 15 | Z31: =+IF(C31*$Y$2>1,1,C31*$Y$2) -> 0.3996 | AA31: =+IF(D31*$Y$2>1,1,D31*$Y$2) -> 0.4185326 | AB31: =+IF(E31*$Y$2>1,1,E31*$Y$2) -> 0.65638977 | AC31: =+IF(F31*$Y$2>1,1,F31*$Y$2) -> 0.82201182 | AD31: =+IF(G31*$Y$2>1,1,G31*$Y$2) -> 0.88603352 | AE31: =+IF(H31*$Y$2>1,1,H31*$Y$2) -> 0.94082277 | AF31: =+IF(I31*$Y$2>1,1,I31*$Y$2) -> 0.98412683 | AG31: =+IF(J31*$Y$2>1,1,J31*$Y$2) -> 0.999 | ... AP31: =+IF(S31*$Y$2>1,1,S31*$Y$2) -> 0.98511194 | AQ31: 1 | AR31: =+IF(U31*$Y$2>1,1,U31*$Y$2) -> 0.99004983 | AS31: =+IF(V31*$Y$2>1,1,V31*$Y$2) -> 0.97044553
A32: 3M | B32: 20 | C32: =+IF(C$12<>$A32,99.9%,1)*MAX(EXP(-$B$2*(ABS(C$13-$B32)/MIN(C$13,$B32))),40%) -> 0.3996 | D32: =+IF(D$12<>$A32,99.9%,1)*MAX(EXP(-$B$2*(ABS(D$13-$B32)/MIN(D$13,$B32))),40%) -> 0.3996 | E32: =+IF(E$12<>$A32,99.9%,1)*MAX(EXP(-$B$2*(ABS(E$13-$B32)/MIN(E$13,$B32))),40%) -> 0.56495991 | F32: =+IF(F$12<>$A32,99.9%,1)*MAX(EXP(-$B$2*(ABS(F$13-$B32)/MIN(F$13,$B32))),40%) -> 0.76261611 | G32: =+IF(G$12<>$A32,99.9%,1)*MAX(EXP(-$B$2*(ABS(G$13-$B32)/MIN(G$13,$B32))),40%) -> 0.84282115 | H32: =+IF(H$12<>$A32,99.9%,1)*MAX(EXP(-$B$2*(ABS(H$13-$B32)/MIN(H$13,$B32))),40%) -> 0.91301725 | I32: =+IF(I$12<>$A32,99.9%,1)*MAX(EXP(-$B$2*(ABS(I$13-$B32)/MIN(I$13,$B32))),40%) -> 0.96947509 | J32: =+IF(J$12<>$A32,99.9%,1)*MAX(EXP(-$B$2*(ABS(J$13-$B32)/MIN(J$13,$B32))),40%) -> 0.98905978 | ... V32: =+IF(V$12<>$A32,99.9%,1)*MAX(EXP(-$B$2*(ABS(V$13-$B32)/MIN(V$13,$B32))),40%) -> 0.98511194 | X32: 3M | Y32: 20 | Z32: =+IF(C32*$Y$2>1,1,C32*$Y$2) -> 0.3996 | AA32: =+IF(D32*$Y$2>1,1,D32*$Y$2) -> 0.3996 | AB32: =+IF(E32*$Y$2>1,1,E32*$Y$2) -> 0.56495991 | AC32: =+IF(F32*$Y$2>1,1,F32*$Y$2) -> 0.76261611 | AD32: =+IF(G32*$Y$2>1,1,G32*$Y$2) -> 0.84282115 | AE32: =+IF(H32*$Y$2>1,1,H32*$Y$2) -> 0.91301725 | AF32: =+IF(I32*$Y$2>1,1,I32*$Y$2) -> 0.96947509 | AG32: =+IF(J32*$Y$2>1,1,J32*$Y$2) -> 0.98905978 | ... AQ32: =+IF(T32*$Y$2>1,1,T32*$Y$2) -> 0.99004983 | AR32: 1 | AS32: =+IF(V32*$Y$2>1,1,V32*$Y$2) -> 0.98511194
A33: 3M | B33: 30 | C33: =+IF(C$12<>$A33,99.9%,1)*MAX(EXP(-$B$2*(ABS(C$13-$B33)/MIN(C$13,$B33))),40%) -> 0.3996 | D33: =+IF(D$12<>$A33,99.9%,1)*MAX(EXP(-$B$2*(ABS(D$13-$B33)/MIN(D$13,$B33))),40%) -> 0.3996 | E33: =+IF(E$12<>$A33,99.9%,1)*MAX(EXP(-$B$2*(ABS(E$13-$B33)/MIN(E$13,$B33))),40%) -> 0.4185326 | F33: =+IF(F$12<>$A33,99.9%,1)*MAX(EXP(-$B$2*(ABS(F$13-$B33)/MIN(F$13,$B33))),40%) -> 0.65638977 | G33: =+IF(G$12<>$A33,99.9%,1)*MAX(EXP(-$B$2*(ABS(G$13-$B33)/MIN(G$13,$B33))),40%) -> 0.76261611 | H33: =+IF(H$12<>$A33,99.9%,1)*MAX(EXP(-$B$2*(ABS(H$13-$B33)/MIN(H$13,$B33))),40%) -> 0.85984727 | I33: =+IF(I$12<>$A33,99.9%,1)*MAX(EXP(-$B$2*(ABS(I$13-$B33)/MIN(I$13,$B33))),40%) -> 0.94082277 | J33: =+IF(J$12<>$A33,99.9%,1)*MAX(EXP(-$B$2*(ABS(J$13-$B33)/MIN(J$13,$B33))),40%) -> 0.96947509 | ... V33: =+IF(V$12<>$A33,99.9%,1)*MAX(EXP(-$B$2*(ABS(V$13-$B33)/MIN(V$13,$B33))),40%) -> 1 | X33: 3M | Y33: 30 | Z33: =+IF(C33*$Y$2>1,1,C33*$Y$2) -> 0.3996 | AA33: =+IF(D33*$Y$2>1,1,D33*$Y$2) -> 0.3996 | AB33: =+IF(E33*$Y$2>1,1,E33*$Y$2) -> 0.4185326 | AC33: =+IF(F33*$Y$2>1,1,F33*$Y$2) -> 0.65638977 | AD33: =+IF(G33*$Y$2>1,1,G33*$Y$2) -> 0.76261611 | AE33: =+IF(H33*$Y$2>1,1,H33*$Y$2) -> 0.85984727 | AF33: =+IF(I33*$Y$2>1,1,I33*$Y$2) -> 0.94082277 | AG33: =+IF(J33*$Y$2>1,1,J33*$Y$2) -> 0.96947509 | ... AR33: =+IF(U33*$Y$2>1,1,U33*$Y$2) -> 0.98511194 | AS33: 1
A35: Ejemplo inflacion y curvas de tipos | X35: Ejemplo inflacion y curvas de tipos
X36: Matriz estresada correlaciones
B37: Curva | C37: {=+TRANSPOSE(A39:A58)} -> 1M | D37: 1M | E37: 1M | F37: 1M | G37: 1M | H37: 1M | I37: 1M | J37: 1M | K37: 1M | L37: 1M | M37: Inflacion | N37: Inflacion | O37: Inflacion | P37: Inflacion | Q37: Inflacion | R37: Inflacion | S37: Inflacion | T37: Inflacion | U37: Inflacion | V37: Inflacion | Y37: Curva | Z37: {=+TRANSPOSE(X39:X58)} -> 1M | AA37: 1M | AB37: 1M | AC37: 1M | AD37: 1M | AE37: 1M | AF37: 1M | AG37: 1M | AH37: 1M | AI37: 1M | AJ37: Inflacion | AK37: Inflacion | AL37: Inflacion | AM37: Inflacion | AN37: Inflacion | AO37: Inflacion | AP37: Inflacion | AQ37: Inflacion | AR37: Inflacion | AS37: Inflacion
A38: Curva | B38: Tenor | C38: {=+TRANSPOSE(B39:B58)} -> 0.25 | D38: 0.5 | E38: 1 | F38: 2 | G38: 3 | H38: 5 | I38: 10 | J38: 15 | K38: 20 | L38: 30 | M38: 0.25 | N38: 0.5 | O38: 1 | P38: 2 | Q38: 3 | R38: 5 | S38: 10 | T38: 15 | U38: 20 | V38: 30 | X38: Curva | Y38: Tenor | Z38: {=+TRANSPOSE(Y39:Y58)} -> 0.25 | AA38: 0.5 | AB38: 1 | AC38: 2 | AD38: 3 | AE38: 5 | AF38: 10 | AG38: 15 | AH38: 20 | AI38: 30 | AJ38: 0.25 | AK38: 0.5 | AL38: 1 | AM38: 2 | AN38: 3 | AO38: 5 | AP38: 10 | AQ38: 15 | AR38: 20 | AS38: 30
A39: 1M | B39: 0.25 | C39: =+IF(C$12<>$A39,99.9%,1)*MAX(EXP(-$B$2*(ABS(C$38-$B39)/MIN(C$38,$B39))),40%) -> 1 | D39: =+IF(D$12<>$A39,99.9%,1)*MAX(EXP(-$B$2*(ABS(D$38-$B39)/MIN(D$38,$B39))),40%) -> 0.97044553 | E39: =+IF(E$12<>$A39,99.9%,1)*MAX(EXP(-$B$2*(ABS(E$38-$B39)/MIN(E$38,$B39))),40%) -> 0.91393119 | F39: =+IF(F$12<>$A39,99.9%,1)*MAX(EXP(-$B$2*(ABS(F$38-$B39)/MIN(F$38,$B39))),40%) -> 0.81058425 | G39: =+IF(G$12<>$A39,99.9%,1)*MAX(EXP(-$B$2*(ABS(G$38-$B39)/MIN(G$38,$B39))),40%) -> 0.71892373 | H39: =+IF(H$12<>$A39,99.9%,1)*MAX(EXP(-$B$2*(ABS(H$38-$B39)/MIN(H$38,$B39))),40%) -> 0.56552544 | I39: =+IF(I$12<>$A39,99.9%,1)*MAX(EXP(-$B$2*(ABS(I$38-$B39)/MIN(I$38,$B39))),40%) -> 0.4 | J39: =+IF(J$12<>$A39,99.9%,1)*MAX(EXP(-$B$2*(ABS(J$38-$B39)/MIN(J$38,$B39))),40%) -> 0.4 | ... L39: =+IF(L$12<>$A39,99.9%,1)*MAX(EXP(-$B$2*(ABS(L$38-$B39)/MIN(L$38,$B39))),40%) -> 0.4 | M39: 0.4 | N39: 0.4 | O39: 0.4 | P39: 0.4 | Q39: 0.4 | R39: 0.4 | S39: 0.4 | T39: 0.4 | U39: 0.4 | V39: 0.4 | X39: 1M | Y39: 0.25 | Z39: 1 | AA39: =+IF(D39*$Y$2>1,1,D39*$Y$2) -> 0.97044553 | AB39: =+IF(E39*$Y$2>1,1,E39*$Y$2) -> 0.91393119 | AC39: =+IF(F39*$Y$2>1,1,F39*$Y$2) -> 0.81058425 | AD39: =+IF(G39*$Y$2>1,1,G39*$Y$2) -> 0.71892373 | AE39: =+IF(H39*$Y$2>1,1,H39*$Y$2) -> 0.56552544 | AF39: =+IF(I39*$Y$2>1,1,I39*$Y$2) -> 0.4 | AG39: =+IF(J39*$Y$2>1,1,J39*$Y$2) -> 0.4 | AH39: =+IF(K39*$Y$2>1,1,K39*$Y$2) -> 0.4 | ... AS39: =+IF(V39*$Y$2>1,1,V39*$Y$2) -> 0.4
A40: 1M | B40: 0.5 | C40: =+IF(C$12<>$A40,99.9%,1)*MAX(EXP(-$B$2*(ABS(C$38-$B40)/MIN(C$38,$B40))),40%) -> 0.97044553 | D40: =+IF(D$12<>$A40,99.9%,1)*MAX(EXP(-$B$2*(ABS(D$38-$B40)/MIN(D$38,$B40))),40%) -> 1 | E40: =+IF(E$12<>$A40,99.9%,1)*MAX(EXP(-$B$2*(ABS(E$38-$B40)/MIN(E$38,$B40))),40%) -> 0.97044553 | F40: =+IF(F$12<>$A40,99.9%,1)*MAX(EXP(-$B$2*(ABS(F$38-$B40)/MIN(F$38,$B40))),40%) -> 0.91393119 | G40: =+IF(G$12<>$A40,99.9%,1)*MAX(EXP(-$B$2*(ABS(G$38-$B40)/MIN(G$38,$B40))),40%) -> 0.86070798 | H40: =+IF(H$12<>$A40,99.9%,1)*MAX(EXP(-$B$2*(ABS(H$38-$B40)/MIN(H$38,$B40))),40%) -> 0.76337949 | I40: =+IF(I$12<>$A40,99.9%,1)*MAX(EXP(-$B$2*(ABS(I$38-$B40)/MIN(I$38,$B40))),40%) -> 0.56552544 | J40: =+IF(J$12<>$A40,99.9%,1)*MAX(EXP(-$B$2*(ABS(J$38-$B40)/MIN(J$38,$B40))),40%) -> 0.41895155 | ... L40: =+IF(L$12<>$A40,99.9%,1)*MAX(EXP(-$B$2*(ABS(L$38-$B40)/MIN(L$38,$B40))),40%) -> 0.4 | M40: 0.4 | N40: 0.4 | O40: 0.4 | P40: 0.4 | Q40: 0.4 | R40: 0.4 | S40: 0.4 | T40: 0.4 | U40: 0.4 | V40: 0.4 | X40: 1M | Y40: 0.5 | Z40: =+IF(C40*$Y$2>1,1,C40*$Y$2) -> 0.97044553 | AA40: 1 | AB40: =+IF(E40*$Y$2>1,1,E40*$Y$2) -> 0.97044553 | AC40: =+IF(F40*$Y$2>1,1,F40*$Y$2) -> 0.91393119 | AD40: =+IF(G40*$Y$2>1,1,G40*$Y$2) -> 0.86070798 | AE40: =+IF(H40*$Y$2>1,1,H40*$Y$2) -> 0.76337949 | AF40: =+IF(I40*$Y$2>1,1,I40*$Y$2) -> 0.56552544 | AG40: =+IF(J40*$Y$2>1,1,J40*$Y$2) -> 0.41895155 | AH40: =+IF(K40*$Y$2>1,1,K40*$Y$2) -> 0.4 | AI40: =+IF(L40*$Y$2>1,1,L40*$Y$2) -> 0.4 | ... AS40: =+IF(V40*$Y$2>1,1,V40*$Y$2) -> 0.4
A41: 1M | B41: 1 | C41: =+IF(C$12<>$A41,99.9%,1)*MAX(EXP(-$B$2*(ABS(C$38-$B41)/MIN(C$38,$B41))),40%) -> 0.91393119 | D41: =+IF(D$12<>$A41,99.9%,1)*MAX(EXP(-$B$2*(ABS(D$38-$B41)/MIN(D$38,$B41))),40%) -> 0.97044553 | E41: =+IF(E$12<>$A41,99.9%,1)*MAX(EXP(-$B$2*(ABS(E$38-$B41)/MIN(E$38,$B41))),40%) -> 1 | F41: =+IF(F$12<>$A41,99.9%,1)*MAX(EXP(-$B$2*(ABS(F$38-$B41)/MIN(F$38,$B41))),40%) -> 0.97044553 | G41: =+IF(G$12<>$A41,99.9%,1)*MAX(EXP(-$B$2*(ABS(G$38-$B41)/MIN(G$38,$B41))),40%) -> 0.94176453 | H41: =+IF(H$12<>$A41,99.9%,1)*MAX(EXP(-$B$2*(ABS(H$38-$B41)/MIN(H$38,$B41))),40%) -> 0.88692044 | I41: =+IF(I$12<>$A41,99.9%,1)*MAX(EXP(-$B$2*(ABS(I$38-$B41)/MIN(I$38,$B41))),40%) -> 0.76337949 | J41: =+IF(J$12<>$A41,99.9%,1)*MAX(EXP(-$B$2*(ABS(J$38-$B41)/MIN(J$38,$B41))),40%) -> 0.65704682 | ... L41: =+IF(L$12<>$A41,99.9%,1)*MAX(EXP(-$B$2*(ABS(L$38-$B41)/MIN(L$38,$B41))),40%) -> 0.41895155 | M41: 0.4 | N41: 0.4 | O41: 0.4 | P41: 0.4 | Q41: 0.4 | R41: 0.4 | S41: 0.4 | T41: 0.4 | U41: 0.4 | V41: 0.4 | X41: 1M | Y41: 1 | Z41: =+IF(C41*$Y$2>1,1,C41*$Y$2) -> 0.91393119 | AA41: =+IF(D41*$Y$2>1,1,D41*$Y$2) -> 0.97044553 | AB41: 1 | AC41: =+IF(F41*$Y$2>1,1,F41*$Y$2) -> 0.97044553 | AD41: =+IF(G41*$Y$2>1,1,G41*$Y$2) -> 0.94176453 | AE41: =+IF(H41*$Y$2>1,1,H41*$Y$2) -> 0.88692044 | AF41: =+IF(I41*$Y$2>1,1,I41*$Y$2) -> 0.76337949 | AG41: =+IF(J41*$Y$2>1,1,J41*$Y$2) -> 0.65704682 | AH41: =+IF(K41*$Y$2>1,1,K41*$Y$2) -> 0.56552544 | AI41: =+IF(L41*$Y$2>1,1,L41*$Y$2) -> 0.41895155 | AJ41: =+IF(M41*$Y$2>1,1,M41*$Y$2) -> 0.4 | ... AS41: =+IF(V41*$Y$2>1,1,V41*$Y$2) -> 0.4
A42: 1M | B42: 2 | C42: =+IF(C$12<>$A42,99.9%,1)*MAX(EXP(-$B$2*(ABS(C$38-$B42)/MIN(C$38,$B42))),40%) -> 0.81058425 | D42: =+IF(D$12<>$A42,99.9%,1)*MAX(EXP(-$B$2*(ABS(D$38-$B42)/MIN(D$38,$B42))),40%) -> 0.91393119 | E42: =+IF(E$12<>$A42,99.9%,1)*MAX(EXP(-$B$2*(ABS(E$38-$B42)/MIN(E$38,$B42))),40%) -> 0.97044553 | F42: =+IF(F$12<>$A42,99.9%,1)*MAX(EXP(-$B$2*(ABS(F$38-$B42)/MIN(F$38,$B42))),40%) -> 1 | G42: =+IF(G$12<>$A42,99.9%,1)*MAX(EXP(-$B$2*(ABS(G$38-$B42)/MIN(G$38,$B42))),40%) -> 0.98511194 | H42: =+IF(H$12<>$A42,99.9%,1)*MAX(EXP(-$B$2*(ABS(H$38-$B42)/MIN(H$38,$B42))),40%) -> 0.95599748 | I42: =+IF(I$12<>$A42,99.9%,1)*MAX(EXP(-$B$2*(ABS(I$38-$B42)/MIN(I$38,$B42))),40%) -> 0.88692044 | J42: =+IF(J$12<>$A42,99.9%,1)*MAX(EXP(-$B$2*(ABS(J$38-$B42)/MIN(J$38,$B42))),40%) -> 0.82283466 | ... L42: =+IF(L$12<>$A42,99.9%,1)*MAX(EXP(-$B$2*(ABS(L$38-$B42)/MIN(L$38,$B42))),40%) -> 0.65704682 | M42: 0.4 | N42: 0.4 | O42: 0.4 | P42: 0.4 | Q42: 0.4 | R42: 0.4 | S42: 0.4 | T42: 0.4 | U42: 0.4 | V42: 0.4 | X42: 1M | Y42: 2 | Z42: =+IF(C42*$Y$2>1,1,C42*$Y$2) -> 0.81058425 | AA42: =+IF(D42*$Y$2>1,1,D42*$Y$2) -> 0.91393119 | AB42: =+IF(E42*$Y$2>1,1,E42*$Y$2) -> 0.97044553 | AC42: 1 | AD42: =+IF(G42*$Y$2>1,1,G42*$Y$2) -> 0.98511194 | AE42: =+IF(H42*$Y$2>1,1,H42*$Y$2) -> 0.95599748 | AF42: =+IF(I42*$Y$2>1,1,I42*$Y$2) -> 0.88692044 | AG42: =+IF(J42*$Y$2>1,1,J42*$Y$2) -> 0.82283466 | AH42: =+IF(K42*$Y$2>1,1,K42*$Y$2) -> 0.76337949 | AI42: =+IF(L42*$Y$2>1,1,L42*$Y$2) -> 0.65704682 | AJ42: =+IF(M42*$Y$2>1,1,M42*$Y$2) -> 0.4 | AK42: =+IF(N42*$Y$2>1,1,N42*$Y$2) -> 0.4 | ... AS42: =+IF(V42*$Y$2>1,1,V42*$Y$2) -> 0.4
A43: 1M | B43: 3 | C43: =+IF(C$12<>$A43,99.9%,1)*MAX(EXP(-$B$2*(ABS(C$38-$B43)/MIN(C$38,$B43))),40%) -> 0.71892373 | D43: =+IF(D$12<>$A43,99.9%,1)*MAX(EXP(-$B$2*(ABS(D$38-$B43)/MIN(D$38,$B43))),40%) -> 0.86070798 | E43: =+IF(E$12<>$A43,99.9%,1)*MAX(EXP(-$B$2*(ABS(E$38-$B43)/MIN(E$38,$B43))),40%) -> 0.94176453 | F43: =+IF(F$12<>$A43,99.9%,1)*MAX(EXP(-$B$2*(ABS(F$38-$B43)/MIN(F$38,$B43))),40%) -> 0.98511194 | G43: =+IF(G$12<>$A43,99.9%,1)*MAX(EXP(-$B$2*(ABS(G$38-$B43)/MIN(G$38,$B43))),40%) -> 1 | H43: =+IF(H$12<>$A43,99.9%,1)*MAX(EXP(-$B$2*(ABS(H$38-$B43)/MIN(H$38,$B43))),40%) -> 0.98019867 | I43: =+IF(I$12<>$A43,99.9%,1)*MAX(EXP(-$B$2*(ABS(I$38-$B43)/MIN(I$38,$B43))),40%) -> 0.93239382 | J43: =+IF(J$12<>$A43,99.9%,1)*MAX(EXP(-$B$2*(ABS(J$38-$B43)/MIN(J$38,$B43))),40%) -> 0.88692044 | ... L43: =+IF(L$12<>$A43,99.9%,1)*MAX(EXP(-$B$2*(ABS(L$38-$B43)/MIN(L$38,$B43))),40%) -> 0.76337949 | M43: 0.4 | N43: 0.4 | O43: 0.4 | P43: 0.4 | Q43: 0.4 | R43: 0.4 | S43: 0.4 | T43: 0.4 | U43: 0.4 | V43: 0.4 | X43: 1M | Y43: 3 | Z43: =+IF(C43*$Y$2>1,1,C43*$Y$2) -> 0.71892373 | AA43: =+IF(D43*$Y$2>1,1,D43*$Y$2) -> 0.86070798 | AB43: =+IF(E43*$Y$2>1,1,E43*$Y$2) -> 0.94176453 | AC43: =+IF(F43*$Y$2>1,1,F43*$Y$2) -> 0.98511194 | AD43: 1 | AE43: =+IF(H43*$Y$2>1,1,H43*$Y$2) -> 0.98019867 | AF43: =+IF(I43*$Y$2>1,1,I43*$Y$2) -> 0.93239382 | AG43: =+IF(J43*$Y$2>1,1,J43*$Y$2) -> 0.88692044 | AH43: =+IF(K43*$Y$2>1,1,K43*$Y$2) -> 0.84366482 | AI43: =+IF(L43*$Y$2>1,1,L43*$Y$2) -> 0.76337949 | AJ43: =+IF(M43*$Y$2>1,1,M43*$Y$2) -> 0.4 | AK43: =+IF(N43*$Y$2>1,1,N43*$Y$2) -> 0.4 | AL43: =+IF(O43*$Y$2>1,1,O43*$Y$2) -> 0.4 | ... AS43: =+IF(V43*$Y$2>1,1,V43*$Y$2) -> 0.4
A44: 1M | B44: 5 | C44: =+IF(C$12<>$A44,99.9%,1)*MAX(EXP(-$B$2*(ABS(C$38-$B44)/MIN(C$38,$B44))),40%) -> 0.56552544 | D44: =+IF(D$12<>$A44,99.9%,1)*MAX(EXP(-$B$2*(ABS(D$38-$B44)/MIN(D$38,$B44))),40%) -> 0.76337949 | E44: =+IF(E$12<>$A44,99.9%,1)*MAX(EXP(-$B$2*(ABS(E$38-$B44)/MIN(E$38,$B44))),40%) -> 0.88692044 | F44: =+IF(F$12<>$A44,99.9%,1)*MAX(EXP(-$B$2*(ABS(F$38-$B44)/MIN(F$38,$B44))),40%) -> 0.95599748 | G44: =+IF(G$12<>$A44,99.9%,1)*MAX(EXP(-$B$2*(ABS(G$38-$B44)/MIN(G$38,$B44))),40%) -> 0.98019867 | H44: =+IF(H$12<>$A44,99.9%,1)*MAX(EXP(-$B$2*(ABS(H$38-$B44)/MIN(H$38,$B44))),40%) -> 1 | I44: =+IF(I$12<>$A44,99.9%,1)*MAX(EXP(-$B$2*(ABS(I$38-$B44)/MIN(I$38,$B44))),40%) -> 0.97044553 | J44: =+IF(J$12<>$A44,99.9%,1)*MAX(EXP(-$B$2*(ABS(J$38-$B44)/MIN(J$38,$B44))),40%) -> 0.94176453 | ... L44: =+IF(L$12<>$A44,99.9%,1)*MAX(EXP(-$B$2*(ABS(L$38-$B44)/MIN(L$38,$B44))),40%) -> 0.86070798 | M44: 0.4 | N44: 0.4 | O44: 0.4 | P44: 0.4 | Q44: 0.4 | R44: 0.4 | S44: 0.4 | T44: 0.4 | U44: 0.4 | V44: 0.4 | X44: 1M | Y44: 5 | Z44: =+IF(C44*$Y$2>1,1,C44*$Y$2) -> 0.56552544 | AA44: =+IF(D44*$Y$2>1,1,D44*$Y$2) -> 0.76337949 | AB44: =+IF(E44*$Y$2>1,1,E44*$Y$2) -> 0.88692044 | AC44: =+IF(F44*$Y$2>1,1,F44*$Y$2) -> 0.95599748 | AD44: =+IF(G44*$Y$2>1,1,G44*$Y$2) -> 0.98019867 | AE44: 1 | AF44: =+IF(I44*$Y$2>1,1,I44*$Y$2) -> 0.97044553 | AG44: =+IF(J44*$Y$2>1,1,J44*$Y$2) -> 0.94176453 | AH44: =+IF(K44*$Y$2>1,1,K44*$Y$2) -> 0.91393119 | AI44: =+IF(L44*$Y$2>1,1,L44*$Y$2) -> 0.86070798 | AJ44: =+IF(M44*$Y$2>1,1,M44*$Y$2) -> 0.4 | AK44: =+IF(N44*$Y$2>1,1,N44*$Y$2) -> 0.4 | AL44: =+IF(O44*$Y$2>1,1,O44*$Y$2) -> 0.4 | AM44: =+IF(P44*$Y$2>1,1,P44*$Y$2) -> 0.4 | ... AS44: =+IF(V44*$Y$2>1,1,V44*$Y$2) -> 0.4
A45: 1M | B45: 10 | C45: =+IF(C$12<>$A45,99.9%,1)*MAX(EXP(-$B$2*(ABS(C$38-$B45)/MIN(C$38,$B45))),40%) -> 0.4 | D45: =+IF(D$12<>$A45,99.9%,1)*MAX(EXP(-$B$2*(ABS(D$38-$B45)/MIN(D$38,$B45))),40%) -> 0.56552544 | E45: =+IF(E$12<>$A45,99.9%,1)*MAX(EXP(-$B$2*(ABS(E$38-$B45)/MIN(E$38,$B45))),40%) -> 0.76337949 | F45: =+IF(F$12<>$A45,99.9%,1)*MAX(EXP(-$B$2*(ABS(F$38-$B45)/MIN(F$38,$B45))),40%) -> 0.88692044 | G45: =+IF(G$12<>$A45,99.9%,1)*MAX(EXP(-$B$2*(ABS(G$38-$B45)/MIN(G$38,$B45))),40%) -> 0.93239382 | H45: =+IF(H$12<>$A45,99.9%,1)*MAX(EXP(-$B$2*(ABS(H$38-$B45)/MIN(H$38,$B45))),40%) -> 0.97044553 | I45: =+IF(I$12<>$A45,99.9%,1)*MAX(EXP(-$B$2*(ABS(I$38-$B45)/MIN(I$38,$B45))),40%) -> 1 | J45: =+IF(J$12<>$A45,99.9%,1)*MAX(EXP(-$B$2*(ABS(J$38-$B45)/MIN(J$38,$B45))),40%) -> 0.98511194 | ... L45: =+IF(L$12<>$A45,99.9%,1)*MAX(EXP(-$B$2*(ABS(L$38-$B45)/MIN(L$38,$B45))),40%) -> 0.94176453 | M45: 0.4 | N45: 0.4 | O45: 0.4 | P45: 0.4 | Q45: 0.4 | R45: 0.4 | S45: 0.4 | T45: 0.4 | U45: 0.4 | V45: 0.4 | X45: 1M | Y45: 10 | Z45: =+IF(C45*$Y$2>1,1,C45*$Y$2) -> 0.4 | AA45: =+IF(D45*$Y$2>1,1,D45*$Y$2) -> 0.56552544 | AB45: =+IF(E45*$Y$2>1,1,E45*$Y$2) -> 0.76337949 | AC45: =+IF(F45*$Y$2>1,1,F45*$Y$2) -> 0.88692044 | AD45: =+IF(G45*$Y$2>1,1,G45*$Y$2) -> 0.93239382 | AE45: =+IF(H45*$Y$2>1,1,H45*$Y$2) -> 0.97044553 | AF45: 1 | AG45: =+IF(J45*$Y$2>1,1,J45*$Y$2) -> 0.98511194 | AH45: =+IF(K45*$Y$2>1,1,K45*$Y$2) -> 0.97044553 | AI45: =+IF(L45*$Y$2>1,1,L45*$Y$2) -> 0.94176453 | AJ45: =+IF(M45*$Y$2>1,1,M45*$Y$2) -> 0.4 | AK45: =+IF(N45*$Y$2>1,1,N45*$Y$2) -> 0.4 | AL45: =+IF(O45*$Y$2>1,1,O45*$Y$2) -> 0.4 | AM45: =+IF(P45*$Y$2>1,1,P45*$Y$2) -> 0.4 | AN45: =+IF(Q45*$Y$2>1,1,Q45*$Y$2) -> 0.4 | ... AS45: =+IF(V45*$Y$2>1,1,V45*$Y$2) -> 0.4
A46: 1M | B46: 15 | C46: =+IF(C$12<>$A46,99.9%,1)*MAX(EXP(-$B$2*(ABS(C$38-$B46)/MIN(C$38,$B46))),40%) -> 0.4 | D46: =+IF(D$12<>$A46,99.9%,1)*MAX(EXP(-$B$2*(ABS(D$38-$B46)/MIN(D$38,$B46))),40%) -> 0.41895155 | E46: =+IF(E$12<>$A46,99.9%,1)*MAX(EXP(-$B$2*(ABS(E$38-$B46)/MIN(E$38,$B46))),40%) -> 0.65704682 | F46: =+IF(F$12<>$A46,99.9%,1)*MAX(EXP(-$B$2*(ABS(F$38-$B46)/MIN(F$38,$B46))),40%) -> 0.82283466 | G46: =+IF(G$12<>$A46,99.9%,1)*MAX(EXP(-$B$2*(ABS(G$38-$B46)/MIN(G$38,$B46))),40%) -> 0.88692044 | H46: =+IF(H$12<>$A46,99.9%,1)*MAX(EXP(-$B$2*(ABS(H$38-$B46)/MIN(H$38,$B46))),40%) -> 0.94176453 | I46: =+IF(I$12<>$A46,99.9%,1)*MAX(EXP(-$B$2*(ABS(I$38-$B46)/MIN(I$38,$B46))),40%) -> 0.98511194 | J46: =+IF(J$12<>$A46,99.9%,1)*MAX(EXP(-$B$2*(ABS(J$38-$B46)/MIN(J$38,$B46))),40%) -> 1 | ... L46: =+IF(L$12<>$A46,99.9%,1)*MAX(EXP(-$B$2*(ABS(L$38-$B46)/MIN(L$38,$B46))),40%) -> 0.97044553 | M46: 0.4 | N46: 0.4 | O46: 0.4 | P46: 0.4 | Q46: 0.4 | R46: 0.4 | S46: 0.4 | T46: 0.4 | U46: 0.4 | V46: 0.4 | X46: 1M | Y46: 15 | Z46: =+IF(C46*$Y$2>1,1,C46*$Y$2) -> 0.4 | AA46: =+IF(D46*$Y$2>1,1,D46*$Y$2) -> 0.41895155 | AB46: =+IF(E46*$Y$2>1,1,E46*$Y$2) -> 0.65704682 | AC46: =+IF(F46*$Y$2>1,1,F46*$Y$2) -> 0.82283466 | AD46: =+IF(G46*$Y$2>1,1,G46*$Y$2) -> 0.88692044 | AE46: =+IF(H46*$Y$2>1,1,H46*$Y$2) -> 0.94176453 | AF46: =+IF(I46*$Y$2>1,1,I46*$Y$2) -> 0.98511194 | AG46: 1 | AH46: =+IF(K46*$Y$2>1,1,K46*$Y$2) -> 0.99004983 | AI46: =+IF(L46*$Y$2>1,1,L46*$Y$2) -> 0.97044553 | AJ46: =+IF(M46*$Y$2>1,1,M46*$Y$2) -> 0.4 | AK46: =+IF(N46*$Y$2>1,1,N46*$Y$2) -> 0.4 | AL46: =+IF(O46*$Y$2>1,1,O46*$Y$2) -> 0.4 | AM46: =+IF(P46*$Y$2>1,1,P46*$Y$2) -> 0.4 | AN46: =+IF(Q46*$Y$2>1,1,Q46*$Y$2) -> 0.4 | AO46: =+IF(R46*$Y$2>1,1,R46*$Y$2) -> 0.4 | ... AS46: =+IF(V46*$Y$2>1,1,V46*$Y$2) -> 0.4
A47: 1M | B47: 20 | C47: =+IF(C$12<>$A47,99.9%,1)*MAX(EXP(-$B$2*(ABS(C$38-$B47)/MIN(C$38,$B47))),40%) -> 0.4 | D47: =+IF(D$12<>$A47,99.9%,1)*MAX(EXP(-$B$2*(ABS(D$38-$B47)/MIN(D$38,$B47))),40%) -> 0.4 | E47: =+IF(E$12<>$A47,99.9%,1)*MAX(EXP(-$B$2*(ABS(E$38-$B47)/MIN(E$38,$B47))),40%) -> 0.56552544 | F47: =+IF(F$12<>$A47,99.9%,1)*MAX(EXP(-$B$2*(ABS(F$38-$B47)/MIN(F$38,$B47))),40%) -> 0.76337949 | G47: =+IF(G$12<>$A47,99.9%,1)*MAX(EXP(-$B$2*(ABS(G$38-$B47)/MIN(G$38,$B47))),40%) -> 0.84366482 | H47: =+IF(H$12<>$A47,99.9%,1)*MAX(EXP(-$B$2*(ABS(H$38-$B47)/MIN(H$38,$B47))),40%) -> 0.91393119 | I47: =+IF(I$12<>$A47,99.9%,1)*MAX(EXP(-$B$2*(ABS(I$38-$B47)/MIN(I$38,$B47))),40%) -> 0.97044553 | J47: =+IF(J$12<>$A47,99.9%,1)*MAX(EXP(-$B$2*(ABS(J$38-$B47)/MIN(J$38,$B47))),40%) -> 0.99004983 | ... L47: =+IF(L$12<>$A47,99.9%,1)*MAX(EXP(-$B$2*(ABS(L$38-$B47)/MIN(L$38,$B47))),40%) -> 0.98511194 | M47: 0.4 | N47: 0.4 | O47: 0.4 | P47: 0.4 | Q47: 0.4 | R47: 0.4 | S47: 0.4 | T47: 0.4 | U47: 0.4 | V47: 0.4 | X47: 1M | Y47: 20 | Z47: =+IF(C47*$Y$2>1,1,C47*$Y$2) -> 0.4 | AA47: =+IF(D47*$Y$2>1,1,D47*$Y$2) -> 0.4 | AB47: =+IF(E47*$Y$2>1,1,E47*$Y$2) -> 0.56552544 | AC47: =+IF(F47*$Y$2>1,1,F47*$Y$2) -> 0.76337949 | AD47: =+IF(G47*$Y$2>1,1,G47*$Y$2) -> 0.84366482 | AE47: =+IF(H47*$Y$2>1,1,H47*$Y$2) -> 0.91393119 | AF47: =+IF(I47*$Y$2>1,1,I47*$Y$2) -> 0.97044553 | AG47: =+IF(J47*$Y$2>1,1,J47*$Y$2) -> 0.99004983 | AH47: 1 | AI47: =+IF(L47*$Y$2>1,1,L47*$Y$2) -> 0.98511194 | AJ47: =+IF(M47*$Y$2>1,1,M47*$Y$2) -> 0.4 | AK47: =+IF(N47*$Y$2>1,1,N47*$Y$2) -> 0.4 | AL47: =+IF(O47*$Y$2>1,1,O47*$Y$2) -> 0.4 | AM47: =+IF(P47*$Y$2>1,1,P47*$Y$2) -> 0.4 | AN47: =+IF(Q47*$Y$2>1,1,Q47*$Y$2) -> 0.4 | AO47: =+IF(R47*$Y$2>1,1,R47*$Y$2) -> 0.4 | AP47: =+IF(S47*$Y$2>1,1,S47*$Y$2) -> 0.4 | ... AS47: =+IF(V47*$Y$2>1,1,V47*$Y$2) -> 0.4
A48: 1M | B48: 30 | C48: =+IF(C$12<>$A48,99.9%,1)*MAX(EXP(-$B$2*(ABS(C$38-$B48)/MIN(C$38,$B48))),40%) -> 0.4 | D48: =+IF(D$12<>$A48,99.9%,1)*MAX(EXP(-$B$2*(ABS(D$38-$B48)/MIN(D$38,$B48))),40%) -> 0.4 | E48: =+IF(E$12<>$A48,99.9%,1)*MAX(EXP(-$B$2*(ABS(E$38-$B48)/MIN(E$38,$B48))),40%) -> 0.41895155 | F48: =+IF(F$12<>$A48,99.9%,1)*MAX(EXP(-$B$2*(ABS(F$38-$B48)/MIN(F$38,$B48))),40%) -> 0.65704682 | G48: =+IF(G$12<>$A48,99.9%,1)*MAX(EXP(-$B$2*(ABS(G$38-$B48)/MIN(G$38,$B48))),40%) -> 0.76337949 | H48: =+IF(H$12<>$A48,99.9%,1)*MAX(EXP(-$B$2*(ABS(H$38-$B48)/MIN(H$38,$B48))),40%) -> 0.86070798 | I48: =+IF(I$12<>$A48,99.9%,1)*MAX(EXP(-$B$2*(ABS(I$38-$B48)/MIN(I$38,$B48))),40%) -> 0.94176453 | J48: =+IF(J$12<>$A48,99.9%,1)*MAX(EXP(-$B$2*(ABS(J$38-$B48)/MIN(J$38,$B48))),40%) -> 0.97044553 | ... L48: =+IF(L$12<>$A48,99.9%,1)*MAX(EXP(-$B$2*(ABS(L$38-$B48)/MIN(L$38,$B48))),40%) -> 1 | M48: 0.4 | N48: 0.4 | O48: 0.4 | P48: 0.4 | Q48: 0.4 | R48: 0.4 | S48: 0.4 | T48: 0.4 | U48: 0.4 | V48: 0.4 | X48: 1M | Y48: 30 | Z48: =+IF(C48*$Y$2>1,1,C48*$Y$2) -> 0.4 | AA48: =+IF(D48*$Y$2>1,1,D48*$Y$2) -> 0.4 | AB48: =+IF(E48*$Y$2>1,1,E48*$Y$2) -> 0.41895155 | AC48: =+IF(F48*$Y$2>1,1,F48*$Y$2) -> 0.65704682 | AD48: =+IF(G48*$Y$2>1,1,G48*$Y$2) -> 0.76337949 | AE48: =+IF(H48*$Y$2>1,1,H48*$Y$2) -> 0.86070798 | AF48: =+IF(I48*$Y$2>1,1,I48*$Y$2) -> 0.94176453 | AG48: =+IF(J48*$Y$2>1,1,J48*$Y$2) -> 0.97044553 | AH48: =+IF(K48*$Y$2>1,1,K48*$Y$2) -> 0.98511194 | AI48: 1 | AJ48: =+IF(M48*$Y$2>1,1,M48*$Y$2) -> 0.4 | AK48: =+IF(N48*$Y$2>1,1,N48*$Y$2) -> 0.4 | AL48: =+IF(O48*$Y$2>1,1,O48*$Y$2) -> 0.4 | AM48: =+IF(P48*$Y$2>1,1,P48*$Y$2) -> 0.4 | AN48: =+IF(Q48*$Y$2>1,1,Q48*$Y$2) -> 0.4 | AO48: =+IF(R48*$Y$2>1,1,R48*$Y$2) -> 0.4 | AP48: =+IF(S48*$Y$2>1,1,S48*$Y$2) -> 0.4 | AQ48: =+IF(T48*$Y$2>1,1,T48*$Y$2) -> 0.4 | ... AS48: =+IF(V48*$Y$2>1,1,V48*$Y$2) -> 0.4
A49: Inflacion | B49: 0.25 | C49: 0.4 | D49: 0.4 | E49: 0.4 | F49: 0.4 | G49: 0.4 | H49: 0.4 | I49: 0.4 | J49: 0.4 | K49: 0.4 | L49: 0.4 | M49: 0 | N49: 0 | O49: 0 | P49: 0 | Q49: 0 | R49: 0 | S49: 0 | T49: 0 | U49: 0 | V49: 0 | X49: Inflacion | Y49: 0.25 | Z49: =+IF(C49*$Y$2>1,1,C49*$Y$2) -> 0.4 | AA49: =+IF(D49*$Y$2>1,1,D49*$Y$2) -> 0.4 | AB49: =+IF(E49*$Y$2>1,1,E49*$Y$2) -> 0.4 | AC49: =+IF(F49*$Y$2>1,1,F49*$Y$2) -> 0.4 | AD49: =+IF(G49*$Y$2>1,1,G49*$Y$2) -> 0.4 | AE49: =+IF(H49*$Y$2>1,1,H49*$Y$2) -> 0.4 | AF49: =+IF(I49*$Y$2>1,1,I49*$Y$2) -> 0.4 | AG49: =+IF(J49*$Y$2>1,1,J49*$Y$2) -> 0.4 | ... AI49: =+IF(L49*$Y$2>1,1,L49*$Y$2) -> 0.4 | AJ49: 1 | AK49: =+IF(N49*$Y$2>1,1,N49*$Y$2) -> 0 | AL49: =+IF(O49*$Y$2>1,1,O49*$Y$2) -> 0 | AM49: =+IF(P49*$Y$2>1,1,P49*$Y$2) -> 0 | AN49: =+IF(Q49*$Y$2>1,1,Q49*$Y$2) -> 0 | AO49: =+IF(R49*$Y$2>1,1,R49*$Y$2) -> 0 | AP49: =+IF(S49*$Y$2>1,1,S49*$Y$2) -> 0 | AQ49: =+IF(T49*$Y$2>1,1,T49*$Y$2) -> 0 | AR49: =+IF(U49*$Y$2>1,1,U49*$Y$2) -> 0 | AS49: =+IF(V49*$Y$2>1,1,V49*$Y$2) -> 0
...

Sheet delta GIRR 1
A1: Ejemplo 1: sensibilidad a una sola curva de la misma divisa
A3: Delta:
C4: Tenor | D4: 0.25 | E4: 0.5 | F4: 1 | G4: 2 | H4: 3 | I4: 5
A5: Curva | B5: 1M | D5: 1000 | E5: 1000 | F5: 1000 | G5: 1000 | H5: 1000 | I5: 1000
A7: RW: sqrt?
A8: SI | C8: Tenor | D8: 0.25 | E8: 0.5 | F8: 1 | G8: 2 | H8: 3 | I8: 5
A9: =+IF(A8="SI",SQRT(2),1) -> 1.4142136 | D9: 170 | E9: 170 | F9: 160 | G9: 130 | H9: 120 | I9: 110
D10: =+D9/$A$9 -> 120.20815 | E10: =+E9/$A$9 -> 120.20815 | F10: =+F9/$A$9 -> 113.13708 | G10: =+G9/$A$9 -> 91.923882 | H10: =+H9/$A$9 -> 84.852814 | I10: =+I9/$A$9 -> 77.781746
A12: Delta x RW | D12: =+D10*D5 -> 120208.15 | E12: =+E10*E5 -> 120208.15 | F12: =+F10*F5 -> 113137.08 | G12: =+G10*G5 -> 91923.882 | H12: =+H10*H5 -> 84852.814 | I12: =+I10*I5 -> 77781.746
A14: Correlaciones:
C15: Curva | D15: {=+TRANSPOSE(B17:B22)} -> 1M | E15: 1M | F15: 1M | G15: 1M | H15: 1M | I15: 1M
B16: Curva | C16: Tenor | D16: {=+TRANSPOSE(C17:C22)} -> 0.25 | E16: 0.5 | F16: 1 | G16: 2 | H16: 3 | I16: 5
B17: 1M | C17: 0.25 | D17: =+correlaciones!Z14 -> 1 | E17: =+correlaciones!AA14 -> 0.97044553 | F17: =+correlaciones!AB14 -> 0.91393119 | G17: =+correlaciones!AC14 -> 0.81058425 | H17: =+correlaciones!AD14 -> 0.71892373 | I17: =+correlaciones!AE14 -> 0.56552544
B18: 1M | C18: 0.5 | D18: =+correlaciones!Z15 -> 0.97044553 | E18: =+correlaciones!AA15 -> 1 | F18: =+correlaciones!AB15 -> 0.97044553 | G18: =+correlaciones!AC15 -> 0.91393119 | H18: =+correlaciones!AD15 -> 0.86070798 | I18: =+correlaciones!AE15 -> 0.76337949
B19: 1M | C19: 1 | D19: =+correlaciones!Z16 -> 0.91393119 | E19: =+correlaciones!AA16 -> 0.97044553 | F19: =+correlaciones!AB16 -> 1 | G19: =+correlaciones!AC16 -> 0.97044553 | H19: =+correlaciones!AD16 -> 0.94176453 | I19: =+correlaciones!AE16 -> 0.88692044
B20: 1M | C20: 2 | D20: =+correlaciones!Z17 -> 0.81058425 | E20: =+correlaciones!AA17 -> 0.91393119 | F20: =+correlaciones!AB17 -> 0.97044553 | G20: =+correlaciones!AC17 -> 1 | H20: =+correlaciones!AD17 -> 0.98511194 | I20: =+correlaciones!AE17 -> 0.95599748
B21: 1M | C21: 3 | D21: =+correlaciones!Z18 -> 0.71892373 | E21: =+correlaciones!AA18 -> 0.86070798 | F21: =+correlaciones!AB18 -> 0.94176453 | G21: =+correlaciones!AC18 -> 0.98511194 | H21: =+correlaciones!AD18 -> 1 | I21: =+correlaciones!AE18 -> 0.98019867
B22: 1M | C22: 5 | D22: =+correlaciones!Z19 -> 0.56552544 | E22: =+correlaciones!AA19 -> 0.76337949 | F22: =+correlaciones!AB19 -> 0.88692044 | G22: =+correlaciones!AC19 -> 0.95599748 | H22: =+correlaciones!AD19 -> 0.98019867 | I22: =+correlaciones!AE19 -> 1
A25: Kb: RW * Rho | D25: {=+MMULT(D12:I12,D17:I22)} -> 519765.44 | E25: 563079.58 | F25: 577759.24 | G25: 566966.75 | H25: 548082.8 | I25: 508922.16
A27: CAPITAL | D27: {=+SQRT(MMULT(D25:I25,TRANSPOSE(D12:I12)))} -> 577703.9
A28: Escenario rho | B28: =+correlaciones!$Y$2 -> 1

Sheet delta GIRR 2
A1: Ejemplo 2: sensibilidad a dos curvas de la misma divisa
A3: Delta:
C4: Tenor | D4: 0.25 | E4: 0.5 | F4: 1 | G4: 2 | H4: 3 | I4: 5
A5: Curva | B5: 1M | D5: 1000 | E5: 1000 | F5: 1000 | G5: 1000 | H5: 1000 | I5: 1000
A6: Curva | B6: 3M | D6: 1000 | E6: 1000 | F6: 1000 | G6: 1000 | H6: 1000 | I6: 1000
A8: RW: sqrt?
A9: SI | C9: Tenor | D9: 0.25 | E9: 0.5 | F9: 1 | G9: 2 | H9: 3 | I9: 5
A10: =+IF(A9="SI",SQRT(2),1) -> 1.4142136 | C10: RW normal | D10: 170 | E10: 170 | F10: 160 | G10: 130 | H10: 120 | I10: 110
C11: RW premiun | D11: =+D10/$A$10 -> 120.20815 | E11: =+E10/$A$10 -> 120.20815 | F11: =+F10/$A$10 -> 113.13708 | G11: =+G10/$A$10 -> 91.923882 | H11: =+H10/$A$10 -> 84.852814 | I11: =+I10/$A$10 -> 77.781746
A13: Delta x RW | C13: 1M | D13: =+D11*D5 -> 120208.15 | E13: =+E11*E5 -> 120208.15 | F13: =+F11*F5 -> 113137.08 | G13: =+G11*G5 -> 91923.882 | H13: =+H11*H5 -> 84852.814 | I13: =+I11*I5 -> 77781.746
C14: 3M | D14: =+D11*D6 -> 120208.15 | E14: =+E11*E6 -> 120208.15 | F14: =+F11*F6 -> 113137.08 | G14: =+G11*G6 -> 91923.882 | H14: =+H11*H6 -> 84852.814 | I14: =+I11*I6 -> 77781.746
A17: Correlaciones:
C18: Curva | D18: {=+TRANSPOSE(B20:B25)} -> 1M | E18: 1M | F18: 1M | G18: 1M | H18: 1M | I18: 1M | J18: 3M | K18: 3M | L18: 3M | M18: 3M | N18: 3M | O18: 3M
B19: Curva | C19: Tenor | D19: {=+TRANSPOSE(C20:C25)} -> 0.25 | E19: 0.5 | F19: 1 | G19: 2 | H19: 3 | I19: 5 | J19: 0.25 | K19: 0.5 | L19: 1 | M19: 2 | N19: 3 | O19: 5
B20: 1M | C20: 0.25 | D20: =+correlaciones!Z14 -> 1 | E20: =+correlaciones!AA14 -> 0.97044553 | F20: =+correlaciones!AB14 -> 0.91393119 | G20: =+correlaciones!AC14 -> 0.81058425 | H20: =+correlaciones!AD14 -> 0.71892373 | I20: =+correlaciones!AE14 -> 0.56552544 | J20: =+correlaciones!AJ14 -> 0.999 | K20: =+correlaciones!AK14 -> 0.96947509 | L20: =+correlaciones!AL14 -> 0.91301725 | M20: =+correlaciones!AM14 -> 0.80977366 | N20: =+correlaciones!AN14 -> 0.71820481 | O20: =+correlaciones!AO14 -> 0.56495991
B21: 1M | C21: 0.5 | D21: =+correlaciones!Z15 -> 0.97044553 | E21: =+correlaciones!AA15 -> 1 | F21: =+correlaciones!AB15 -> 0.97044553 | G21: =+correlaciones!AC15 -> 0.91393119 | H21: =+correlaciones!AD15 -> 0.86070798 | I21: =+correlaciones!AE15 -> 0.76337949 | J21: =+correlaciones!AJ15 -> 0.96947509 | K21: =+correlaciones!AK15 -> 0.999 | L21: =+correlaciones!AL15 -> 0.96947509 | M21: =+correlaciones!AM15 -> 0.91301725 | N21: =+correlaciones!AN15 -> 0.85984727 | O21: =+correlaciones!AO15 -> 0.76261611
B22: 1M | C22: 1 | D22: =+correlaciones!Z16 -> 0.91393119 | E22: =+correlaciones!AA16 -> 0.97044553 | F22: =+correlaciones!AB16 -> 1 | G22: =+correlaciones!AC16 -> 0.97044553 | H22: =+correlaciones!AD16 -> 0.94176453 | I22: =+correlaciones!AE16 -> 0.88692044 | J22: =+correlaciones!AJ16 -> 0.91301725 | K22: =+correlaciones!AK16 -> 0.96947509 | L22: =+correlaciones!AL16 -> 0.999 | M22: =+correlaciones!AM16 -> 0.96947509 | N22: =+correlaciones!AN16 -> 0.94082277 | O22: =+correlaciones!AO16 -> 0.88603352
B23: 1M | C23: 2 | D23: =+correlaciones!Z17 -> 0.81058425 | E23: =+correlaciones!AA17 -> 0.91393119 | F23: =+correlaciones!AB17 -> 0.97044553 | G23: =+correlaciones!AC17 -> 1 | H23: =+correlaciones!AD17 -> 0.98511194 | I23: =+correlaciones!AE17 -> 0.95599748 | J23: =+correlaciones!AJ17 -> 0.80977366 | K23: =+correlaciones!AK17 -> 0.91301725 | L23: =+correlaciones!AL17 -> 0.96947509 | M23: =+correlaciones!AM17 -> 0.999 | N23: =+correlaciones!AN17 -> 0.98412683 | O23: =+correlaciones!AO17 -> 0.95504148
B24: 1M | C24: 3 | D24: =+correlaciones!Z18 -> 0.71892373 | E24: =+correlaciones!AA18 -> 0.86070798 | F24: =+correlaciones!AB18 -> 0.94176453 | G24: =+correlaciones!AC18 -> 0.98511194 | H24: =+correlaciones!AD18 -> 1 | I24: =+correlaciones!AE18 -> 0.98019867 | J24: =+correlaciones!AJ18 -> 0.71820481 | K24: =+correlaciones!AK18 -> 0.85984727 | L24: =+correlaciones!AL18 -> 0.94082277 | M24: =+correlaciones!AM18 -> 0.98412683 | N24: =+correlaciones!AN18 -> 0.999 | O24: =+correlaciones!AO18 -> 0.97921847
B25: 1M | C25: 5 | D25: =+correlaciones!Z19 -> 0.56552544 | E25: =+correlaciones!AA19 -> 0.76337949 | F25: =+correlaciones!AB19 -> 0.88692044 | G25: =+correlaciones!AC19 -> 0.95599748 | H25: =+correlaciones!AD19 -> 0.98019867 | I25: =+correlaciones!AE19 -> 1 | J25: =+correlaciones!AJ19 -> 0.56495991 | K25: =+correlaciones!AK19 -> 0.76261611 | L25: =+correlaciones!AL19 -> 0.88603352 | M25: =+correlaciones!AM19 -> 0.95504148 | N25: =+correlaciones!AN19 -> 0.97921847 | O25: =+correlaciones!AO19 -> 0.999
B26: 3M | C26: 0.25 | D26: =+correlaciones!Z24 -> 0.999 | E26: =+correlaciones!AA24 -> 0.96947509 | F26: =+correlaciones!AB24 -> 0.91301725 | G26: =+correlaciones!AC24 -> 0.80977366 | H26: =+correlaciones!AD24 -> 0.71820481 | I26: =+correlaciones!AE24 -> 0.56495991 | J26: =+correlaciones!AJ24 -> 1 | K26: =+correlaciones!AK24 -> 0.97044553 | L26: =+correlaciones!AL24 -> 0.91393119 | M26: =+correlaciones!AM24 -> 0.81058425 | N26: =+correlaciones!AN24 -> 0.71892373 | O26: =+correlaciones!AO24 -> 0.56552544
